Workbook

Sheet Introduction
A1: 1 May - Berlin (DGB) and Warsaw (OPZZ), 1990-2019
A2: Consolidated workbook for the annual report: attendance, weather, event breakdown, event structure, sources
A5: Contents:
A6: - Attendance - Warsaw / Attendance - Berlin: yearly 1 May attendance, day of week, length of the May holiday weekend, union share of total attendance, 3-year moving average.
A7: - Weather: legacy morning-weather estimate (Open-Meteo data).
A8: - Events - Warsaw / Events - Berlin: detailed breakdown into the individual marches/events that make up 1 May in each city and year.
A9: - Event structure & rally location: event-type counts per year (demonstrations, festivals, commemorations, rallies, counter-demonstrations, meetings, happenings, corsos) and the main rally/festival location per year.
A10: - Sources - Observations / Averages (Berlin, Warsaw): individual cited estimates (press / organisers / police where available) behind the yearly averages.
A11: - Berlin - unrest vs turnout: police deployment, injuries and arrests around 1 May vs. DGB attendance.

Sheet Attendance - Warsaw
A1: 1 May attendance - Warsaw, 1990-2019
A2: Day of week, length of the May holiday weekend, union attendance, share of total, 3-year moving average
A4: Year | B4: Day of week | C4: Weekend length (days) | D4: Union attendance | E4: Total attendance (all events) | F4: Union share of total | G4: 3-yr moving union share
A5: 1990 | B5: Tuesday | D5: ='Events - Warsaw'!B5 -> 14250 | E5: {='Events - Warsaw'!J5} -> 17550 | F5: {=IFERROR(D5/E5,"")} -> 0.81196581
A6: 1991 | B6: Wednesday | D6: ='Events - Warsaw'!B6 -> 12500 | E6: {='Events - Warsaw'!J6} -> 13030 | F6: {=IFERROR(D6/E6,"")} -> 0.95932464 | G6: {=AVERAGE(F5:F7)} -> 0.91696076
A7: 1992 | B7: Friday | C7: 3 | D7: ='Events - Warsaw'!B7 -> 24000 | E7: {='Events - Warsaw'!J7} -> 24500 | F7: {=IFERROR(D7/E7,"")} -> 0.97959184 | G7: {=AVERAGE(F6:F8)} -> 0.96417491
A8: 1993 | B8: Saturday | C8: 3 | D8: ='Events - Warsaw'!B8 -> 6166.6667 | E8: {='Events - Warsaw'!J8} -> 6466.6667 | F8: {=IFERROR(D8/E8,"")} -> 0.95360825 | G8: {=AVERAGE(F7:F9)} -> 0.93851768
A9: 1994 | B9: Sunday | C9: 3 | D9: ='Events - Warsaw'!B9 -> 3000 | E9: {='Events - Warsaw'!J9} -> 3400 | F9: {=IFERROR(D9/E9,"")} -> 0.88235294 | G9: {=AVERAGE(F8:F10)} -> 0.89607797
A10: 1995 | B10: Monday | C10: 4 | D10: ='Events - Warsaw'!B10 -> 4500 | E10: {='Events - Warsaw'!J10} -> 5280 | F10: {=IFERROR(D10/E10,"")} -> 0.85227273 | G10: {=AVERAGE(F9:F11)} -> 0.8723262
A11: 1996 | B11: Wednesday | C11: 5 | D11: ='Events - Warsaw'!B11 -> 4500 | E11: {='Events - Warsaw'!J11} -> 5100 | F11: {=IFERROR(D11/E11,"")} -> 0.88235294 | G11: {=AVERAGE(F10:F12)} -> 0.89267396
A12: 1997 | B12: Thursday | C12: 4 | D12: ='Events - Warsaw'!B12 -> 2500 | E12: {='Events - Warsaw'!J12} -> 2650 | F12: {=IFERROR(D12/E12,"")} -> 0.94339623 | G12: {=AVERAGE(F11:F13)} -> 0.9298682
A13: 1998 | B13: Friday | C13: 3 | D13: ='Events - Warsaw'!B13 -> 4000 | E13: {='Events - Warsaw'!J13} -> 4150 | F13: {=IFERROR(D13/E13,"")} -> 0.96385542 | G13: {=AVERAGE(F12:F14)} -> 0.96373629
A14: 1999 | B14: Saturday | C14: 3 | D14: ='Events - Warsaw'!B14 -> 9200 | E14: {='Events - Warsaw'!J14} -> 9350 | F14: {=IFERROR(D14/E14,"")} -> 0.98395722 | G14: {=AVERAGE(F13:F15)} -> 0.95539333
A15: 2000 | B15: Monday | C15: 3 | D15: ='Events - Warsaw'!B15 -> 2250 | E15: {='Events - Warsaw'!J15} -> 2450 | F15: {=IFERROR(D15/E15,"")} -> 0.91836735 | G15: {=AVERAGE(F14:F16)} -> 0.94085666
A16: 2001 | B16: Tuesday | C16: 6 | D16: ='Events - Warsaw'!B16 -> 7500 | E16: {='Events - Warsaw'!J16} -> 8150 | F16: {=IFERROR(D16/E16,"")} -> 0.9202454 | G16: {=AVERAGE(F15:F17)} -> 0.79708144
A17: 2002 | B17: Wednesday | C17: 5 | D17: ='Events - Warsaw'!B17 -> 2100 | E17: {='Events - Warsaw'!J17} -> 3800 | F17: {=IFERROR(D17/E17,"")} -> 0.55263158 | G17: {=AVERAGE(F16:F18)} -> 0.6365194
A18: 2003 | B18: Thursday | C18: 4 | D18: ='Events - Warsaw'!B18 -> 3333.3333 | E18: {='Events - Warsaw'!J18} -> 7633.3333 | F18: {=IFERROR(D18/E18,"")} -> 0.43668122 | G18: {=AVERAGE(F17:F19)} -> 0.40729031
... A33: 2018 | B33: Tuesday | C33: 6 | D33: ='Events - Warsaw'!B33 -> 775 | E33: {='Events - Warsaw'!J33} -> 1225 | F33: {=IFERROR(D33/E33,"")} -> 0.63265306 | G33: {=AVERAGE(F32:F34)} -> 0.41723356
A34: 2019 | B34: Wednesday | C34: 5 | D34: ='Events - Warsaw'!B34 -> 0 | E34: {='Events - Warsaw'!J34} -> 3350 | F34: {=IFERROR(D34/E34,"")} -> 0
C36: Average | D36: {=AVERAGE(D5:D34)} -> 5134.9365
C37: Median | D37: {=MEDIAN(D5:D34)} -> 2750
C38: Maximum | D38: {=MAX(D5:D34)} -> 24000
C39: Minimum | D39: {=MIN(D5:D34)} -> 0

Sheet Attendance - Berlin
A1: 1 May attendance - Berlin, 1990-2019
A2: Day of week, length of the May holiday weekend, union attendance, share of total, 3-year moving average
A4: Year | B4: Day of week | C4: Weekend length (days) | D4: Union attendance | E4: Total attendance (all events) | F4: Union share of total | G4: 3-yr moving share (union)
A5: 1990 | B5: Tuesday | D5: ='Events - Berlin'!B5 -> 56666.667 | E5: {='Events - Berlin'!N5} -> 84666.667 | F5: {=IFERROR(D5/E5,"")} -> 0.66929134
A6: 1991 | B6: Wednesday | D6: ='Events - Berlin'!B6 -> 10000 | E6: {='Events - Berlin'!N6} -> 22666.667 | F6: {=IFERROR(D6/E6,"")} -> 0.44117647 | G6: {=AVERAGE(F5:F7)} -> 0.55601452
A7: 1992 | B7: Friday | C7: 3 | D7: ='Events - Berlin'!B7 -> 23000 | E7: {='Events - Berlin'!N7} -> 41250 | F7: {=IFERROR(D7/E7,"")} -> 0.55757576 | G7: {=AVERAGE(F6:F8)} -> 0.51496729
A8: 1993 | B8: Saturday | C8: 2 | D8: ='Events - Berlin'!B8 -> 16666.667 | E8: {='Events - Berlin'!N8} -> 30516.667 | F8: {=IFERROR(D8/E8,"")} -> 0.54614964 | G8: {=AVERAGE(F7:F9)} -> 0.60728609
A9: 1994 | B9: Sunday | C9: 2 | D9: ='Events - Berlin'!B9 -> 6000 | E9: {='Events - Berlin'!N9} -> 8355 | F9: {=IFERROR(D9/E9,"")} -> 0.71813285 | G9: {=AVERAGE(F8:F10)} -> 0.64068676
A10: 1995 | B10: Monday | C10: 3 | D10: ='Events - Berlin'!B10 -> 7400 | E10: {='Events - Berlin'!N10} -> 11250 | F10: {=IFERROR(D10/E10,"")} -> 0.65777778 | G10: {=AVERAGE(F9:F11)} -> 0.63086656
A11: 1996 | B11: Wednesday | D11: ='Events - Berlin'!B11 -> 16666.667 | E11: {='Events - Berlin'!N11} -> 32256.667 | F11: {=IFERROR(D11/E11,"")} -> 0.51668906 | G11: {=AVERAGE(F10:F12)} -> 0.5052614
A12: 1997 | B12: Thursday | C12: 4 | D12: ='Events - Berlin'!B12 -> 9500 | E12: {='Events - Berlin'!N12} -> 27833.333 | F12: {=IFERROR(D12/E12,"")} -> 0.34131737 | G12: {=AVERAGE(F11:F13)} -> 0.4386844
A13: 1998 | B13: Friday | C13: 3 | D13: ='Events - Berlin'!B13 -> 13875 | E13: {='Events - Berlin'!N13} -> 30291.667 | F13: {=IFERROR(D13/E13,"")} -> 0.45804677 | G13: {=AVERAGE(F12:F14)} -> 0.36301924
A14: 1999 | B14: Saturday | C14: 2 | D14: ='Events - Berlin'!B14 -> 10400 | E14: {='Events - Berlin'!N14} -> 35900 | F14: {=IFERROR(D14/E14,"")} -> 0.28969359 | G14: {=AVERAGE(F13:F15)} -> 0.33117391
A15: 2000 | B15: Monday | C15: 3 | D15: ='Events - Berlin'!B15 -> 11166.667 | E15: {='Events - Berlin'!N15} -> 45433.333 | F15: {=IFERROR(D15/E15,"")} -> 0.24578136 | G15: {=AVERAGE(F14:F16)} -> 0.32848794
A16: 2001 | B16: Tuesday | D16: ='Events - Berlin'!B16 -> 16833.333 | E16: {='Events - Berlin'!N16} -> 37408.333 | F16: {=IFERROR(D16/E16,"")} -> 0.44998886 | G16: {=AVERAGE(F15:F17)} -> 0.37731921
A17: 2002 | B17: Wednesday | D17: ='Events - Berlin'!B17 -> 13500 | E17: {='Events - Berlin'!N17} -> 30950 | F17: {=IFERROR(D17/E17,"")} -> 0.4361874 | G17: {=AVERAGE(F16:F18)} -> 0.36391131
A18: 2003 | B18: Thursday | C18: 4 | D18: ='Events - Berlin'!B18 -> 13500 | E18: {='Events - Berlin'!N18} -> 65675 | F18: {=IFERROR(D18/E18,"")} -> 0.20555767 | G18: {=AVERAGE(F17:F19)} -> 0.31226696
A19: 2004 | B19: Saturday | C19: 2 | D19: ='Events - Berlin'!B19 -> 18500 | E19: {='Events - Berlin'!N19} -> 62700 | F19: {=IFERROR(D19/E19,"")} -> 0.29505582 | G19: {=AVERAGE(F18:F20)} -> 0.30148655
A20: 2005 | B20: Sunday | C20: 2 | D20: ='Events - Berlin'!B20 -> 10500 | E20: {='Events - Berlin'!N20} -> 26000 | F20: {=IFERROR(D20/E20,"")} -> 0.40384615 | G20: {=AVERAGE(F19:F21)} -> 0.39058554
A21: 2006 | B21: Monday | C21: 3 | D21: ='Events - Berlin'!B21 -> 13500 | E21: {='Events - Berlin'!N21} -> 28550 | F21: {=IFERROR(D21/E21,"")} -> 0.47285464 | G21: {=AVERAGE(F20:F22)} -> 0.34365377
A22: 2007 | B22: Tuesday | D22: ='Events - Berlin'!B22 -> 10500 | E22: {='Events - Berlin'!N22} -> 68066.667 | F22: {=IFERROR(D22/E22,"")} -> 0.15426053 | G22: {=AVERAGE(F21:F23)} -> 0.27385814
A23: 2008 | B23: Thursday | C23: 4 | D23: ='Events - Berlin'!B23 -> 9125 | E23: {='Events - Berlin'!N23} -> 46925 | F23: {=IFERROR(D23/E23,"")} -> 0.19445924 | G23: {=AVERAGE(F22:F24)} -> 0.18600737
A24: 2009 | B24: Friday | C24: 3 | D24: ='Events - Berlin'!B24 -> 13500 | E24: {='Events - Berlin'!N24} -> 64500 | F24: {=IFERROR(D24/E24,"")} -> 0.20930233 | G24: {=AVERAGE(F23:F25)} -> 0.18700654
A25: 2010 | B25: Saturday | C25: 2 | D25: ='Events - Berlin'!B25 -> 9750 | E25: {='Events - Berlin'!N25} -> 62000 | F25: {=IFERROR(D25/E25,"")} -> 0.15725806 | G25: {=AVERAGE(F24:F26)} -> 0.19910987
A26: 2011 | B26: Sunday | C26: 2 | D26: ='Events - Berlin'!B26 -> 11500 | E26: {='Events - Berlin'!N26} -> 49833.333 | F26: {=IFERROR(D26/E26,"")} -> 0.23076923 | G26: {=AVERAGE(F25:F27)} -> 0.19672068
A27: 2012 | B27: Tuesday | D27: ='Events - Berlin'!B27 -> 12625 | E27: {='Events - Berlin'!N27} -> 62458.333 | F27: {=IFERROR(D27/E27,"")} -> 0.20213476 | G27: {=AVERAGE(F26:F28)} -> 0.19530839
A28: 2013 | B28: Wednesday | D28: ='Events - Berlin'!B28 -> 9750 | E28: {='Events - Berlin'!N28} -> 63716.667 | F28: {=IFERROR(D28/E28,"")} -> 0.15302119 | G28: {=AVERAGE(F27:F29)} -> 0.16468161
A29: 2014 | B29: Thursday | C29: 4 | D29: ='Events - Berlin'!B29 -> 10000 | E29: {='Events - Berlin'!N29} -> 72000 | F29: {=IFERROR(D29/E29,"")} -> 0.13888889 | G29: {=AVERAGE(F28:F30)} -> 0.15540911
A30: 2015 | B30: Friday | C30: 3 | D30: ='Events - Berlin'!B30 -> 15000 | E30: {='Events - Berlin'!N30} -> 86050 | F30: {=IFERROR(D30/E30,"")} -> 0.17431726 | G30: {=AVERAGE(F29:F31)} -> 0.18003684
A31: 2016 | B31: Sunday | C31: 2 | D31: ='Events - Berlin'!B31 -> 14000 | E31: {='Events - Berlin'!N31} -> 61700 | F31: {=IFERROR(D31/E31,"")} -> 0.22690438 | G31: {=AVERAGE(F30:F32)} -> 0.19604584
A32: 2017 | B32: Monday | C32: 3 | D32: ='Events - Berlin'!B32 -> 14000 | E32: {='Events - Berlin'!N32} -> 74900 | F32: {=IFERROR(D32/E32,"")} -> 0.18691589 | G32: {=AVERAGE(F31:F33)} -> 0.17881085
A33: 2018 | B33: Tuesday | D33: ='Events - Berlin'!B33 -> 9500 | E33: {='Events - Berlin'!N33} -> 77480 | F33: {=IFERROR(D33/E33,"")} -> 0.12261229 | G33: {=AVERAGE(F32:F34)} -> 0.16239483
A34: 2019 | B34: Wednesday | D34: ='Events - Berlin'!B34 -> 13000 | E34: {='Events - Berlin'!N34} -> 73175 | F34: {=IFERROR(D34/E34,"")} -> 0.1776563
C36: Average | D36: {=AVERAGE(D5:D34)} -> 13997.5
C37: Median | D37: {=MEDIAN(D5:D34)} -> 12812.5
C38: Maximum | D38: {=MAX(D5:D34)} -> 56666.667
C39: Minimum | D39: {=MIN(D5:D34)} -> 6000

Sheet Weather
A1: Weather on 1 May - Warsaw and Berlin, 1990-2019
A2: LEGACY ESTIMATE - see note below. Not sourced from Open-Meteo.
A3: Source: https://archive-api.open-meteo.com/
A10: Year | B10: Warsaw - morning temp (C, legacy) | C10: Warsaw - precipitation (mm, legacy) | D10: Berlin - morning temp (C, legacy) | E10: Berlin - precipitation (mm, legacy)
A11: 1990 | B11: 11.1 | C11: 0 | D11: 13.2 | E11: 0
A12: 1991 | B12: 8.8 | C12: 0 | D12: 6.7 | E12: 3.2
A13: 1992 | B13: 10.5 | C13: 0 | D13: 12.6 | E13: 0
A14: 1993 | B14: 16.9 | C14: 0 | D14: 18.8 | E14: 0
A15: 1994 | B15: 10 | C15: 0.1 | D15: 7.8 | E15: 0
A16: 1995 | B16: 8.2 | C16: 0 | D16: 11.2 | E16: 0
A17: 1996 | B17: 13.4 | C17: 0.6 | D17: 11.6 | E17: 0
A18: 1997 | B18: 9.2 | C18: 0 | D18: 10.3 | E18: 0.1
A19: 1998 | B19: 15.2 | C19: 0 | D19: 15.8 | E19: 0
A20: 1999 | B20: 10.8 | C20: 0 | D20: 9.1 | E20: 0
A21: 2000 | B21: 19.9 | C21: 0 | D21: 18.1 | E21: 0
A22: 2001 | B22: 18.9 | C22: 0 | D22: 16.3 | E22: 0
... A40: 2019 | B40: 13.9 | C40: 0 | D40: 11.8 | E40: 0.1

Sheet Events - Warsaw
A1: 1 May events - detailed breakdown, Warsaw
A2: Attendance by individual event/march making up 1 May each year
A4: Year | B4: OPZZ / trade unions (main march) | C4: PPS | D4: Alternative Left (W4) | E4: Anarchists (W8) | F4: Right-wing / Nationalists | G4: Equality Parade | H4: Solidarity mass (1990-1994) | I4: UPR rally (1995, one-off) | J4: Total | K4: Total-trade union
A5: 1990 | B5: ='Sources - Averages (Warsaw)'!D5 -> 14250 | D5: 250 | E5: 50 | H5: 3000 | J5: {=SUM(B5:I5)} -> 17550 | K5: =J5-B5 -> 3300
A6: 1991 | B6: ='Sources - Averages (Warsaw)'!D6 -> 12500 | C6: 200 | E6: 30 | H6: 300 | J6: {=SUM(B6:I6)} -> 13030 | K6: =J6-B6 -> 530
A7: 1992 | B7: ='Sources - Averages (Warsaw)'!D7 -> 24000 | C7: 200 | H7: 300 | J7: {=SUM(B7:I7)} -> 24500 | K7: =J7-B7 -> 500
A8: 1993 | B8: ='Sources - Averages (Warsaw)'!D8 -> 6166.6667 | H8: 300 | J8: {=SUM(B8:I8)} -> 6466.6667 | K8: =J8-B8 -> 300
A9: 1994 | B9: ='Sources - Averages (Warsaw)'!D9 -> 3000 | C9: 100 | H9: 300 | J9: {=SUM(B9:I9)} -> 3400 | K9: =J9-B9 -> 400
A10: 1995 | B10: ='Sources - Averages (Warsaw)'!D10 -> 4500 | C10: 80 | E10: 400 | F10: 100 | I10: 200 | J10: {=SUM(B10:I10)} -> 5280 | K10: =J10-B10 -> 780
A11: 1996 | B11: ='Sources - Averages (Warsaw)'!D11 -> 4500 | C11: 100 | E11: 500 | J11: {=SUM(B11:I11)} -> 5100 | K11: =J11-B11 -> 600
A12: 1997 | B12: ='Sources - Averages (Warsaw)'!D12 -> 2500 | C12: 150 | J12: {=SUM(B12:I12)} -> 2650 | K12: =J12-B12 -> 150
A13: 1998 | B13: ='Sources - Averages (Warsaw)'!D13 -> 4000 | C13: 150 | J13: {=SUM(B13:I13)} -> 4150 | K13: =J13-B13 -> 150
A14: 1999 | B14: ='Sources - Averages (Warsaw)'!D14 -> 9200 | C14: 150 | J14: {=SUM(B14:I14)} -> 9350 | K14: =J14-B14 -> 150
A15: 2000 | B15: ='Sources - Averages (Warsaw)'!D15 -> 2250 | C15: 150 | F15: 50 | J15: {=SUM(B15:I15)} -> 2450 | K15: =J15-B15 -> 200
A16: 2001 | B16: ='Sources - Averages (Warsaw)'!D16 -> 7500 | C16: 150 | E16: 300 | G16: 200 | J16: {=SUM(B16:I16)} -> 8150 | K16: =J16-B16 -> 650
A17: 2002 | B17: ='Sources - Averages (Warsaw)'!D17 -> 2100 | D17: 200 | G17: 1500 | J17: {=SUM(B17:I17)} -> 3800 | K17: =J17-B17 -> 1700
A18: 2003 | B18: ='Sources - Averages (Warsaw)'!D18 -> 3333.3333 | D18: 500 | E18: 300 | G18: 3500 | J18: {=SUM(B18:I18)} -> 7633.3333 | K18: =J18-B18 -> 4300
A19: 2004 | B19: ='Sources - Averages (Warsaw)'!D19 -> 666.66667 | D19: 200 | F19: 2000 | J19: {=SUM(B19:I19)} -> 2866.6667 | K19: =J19-B19 -> 2200
A20: 2005 | B20: ='Sources - Averages (Warsaw)'!D20 -> 633.33333 | D20: 300 | J20: {=SUM(B20:I20)} -> 933.33333 | K20: =J20-B20 -> 300
A21: 2006 | B21: ='Sources - Averages (Warsaw)'!D21 -> 1520 | D21: 250 | J21: {=SUM(B21:I21)} -> 1770 | K21: =J21-B21 -> 250
A22: 2007 | B22: ='Sources - Averages (Warsaw)'!D22 -> 1400 | D22: 300 | E22: 80 | J22: {=SUM(B22:I22)} -> 1780 | K22: =J22-B22 -> 380
A23: 2008 | B23: ='Sources - Averages (Warsaw)'!D23 -> 2214.2857 | D23: 200 | E23: 200 | J23: {=SUM(B23:I23)} -> 2614.2857 | K23: =J23-B23 -> 400
A24: 2009 | B24: ='Sources - Averages (Warsaw)'!D24 -> 1357.1429 | D24: 300 | E24: 40 | F24: 6 | J24: {=SUM(B24:I24)} -> 1703.1429 | K24: =J24-B24 -> 346
A25: 2010 | B25: ='Sources - Averages (Warsaw)'!D25 -> 440 | D25: 150 | J25: {=SUM(B25:I25)} -> 590 | K25: =J25-B25 -> 150
A26: 2011 | B26: ='Sources - Averages (Warsaw)'!D26 -> 133.33333 | D26: 150 | J26: {=SUM(B26:I26)} -> 283.33333 | K26: =J26-B26 -> 150
A27: 2012 | B27: ='Sources - Averages (Warsaw)'!D27 -> 11750 | E27: 150 | F27: 500 | J27: {=SUM(B27:I27)} -> 12400 | K27: =J27-B27 -> 650
A28: 2013 | B28: ='Sources - Averages (Warsaw)'!D28 -> 20000 | D28: 200 | F28: 500 | J28: {=SUM(B28:I28)} -> 20700 | K28: =J28-B28 -> 700 | O28: s
A29: 2014 | B29: ='Sources - Averages (Warsaw)'!D29 -> 7333.3333 | D29: 400 | F29: 450 | J29: {=SUM(B29:I29)} -> 8183.3333 | K29: =J29-B29 -> 850
A30: 2015 | B30: ='Sources - Averages (Warsaw)'!D30 -> 0 | D30: 450 | F30: 250 | J30: {=SUM(B30:I30)} -> 700 | K30: =J30-B30 -> 700
A31: 2016 | B31: ='Sources - Averages (Warsaw)'!D31 -> 5375 | D31: 400 | F31: 150 | J31: {=SUM(B31:I31)} -> 5925 | K31: =J31-B31 -> 550
A32: 2017 | B32: ='Sources - Averages (Warsaw)'!D32 -> 650 | D32: 400 | J32: {=SUM(B32:I32)} -> 1050 | K32: =J32-B32 -> 400
A33: 2018 | B33: ='Sources - Averages (Warsaw)'!D33 -> 775 | D33: 400 | F33: 50 | J33: {=SUM(B33:I33)} -> 1225 | K33: =J33-B33 -> 450
A34: 2019 | B34: ='Sources - Averages (Warsaw)'!D34 -> 0 | D34: 350 | F34: 3000 | J34: {=SUM(B34:I34)} -> 3350 | K34: =J34-B34 -> 3350
A36: Average attendance per event (years with data):
A37: OPZZ / trade unions (main march) | B37: {=IFERROR(AVERAGE(B5:B34),"-")} -> 5134.9365 | C37: {=COUNT(B5:B34)} -> 30 | D37: years with data
A38: PPS | B38: {=IFERROR(AVERAGE(C5:C34),"-")} -> 143 | C38: {=COUNT(C5:C34)} -> 10 | D38: years with data
A39: Alternative Left (W4) | B39: {=IFERROR(AVERAGE(D5:D34),"-")} -> 300 | C39: {=COUNT(D5:D34)} -> 18 | D39: years with data
A40: Anarchists (W8) | B40: {=IFERROR(AVERAGE(E5:E34),"-")} -> 205 | C40: {=COUNT(E5:E34)} -> 10 | D40: years with data
A41: Right-wing / Nationalists | B41: {=IFERROR(AVERAGE(F5:F34),"-")} -> 641.45455 | C41: {=COUNT(F5:F34)} -> 11 | D41: years with data
A42: Equality Parade | B42: {=IFERROR(AVERAGE(G5:G34),"-")} -> 1733.3333 | C42: {=COUNT(G5:G34)} -> 3 | D42: years with data
...

Sheet Events - Berlin
A1: 1 May events - detailed breakdown, Berlin
A2: Attendance by individual event/march making up 1 May each year
A4: Year | B4: DGB Berlin (main trade-union rally) | C4: PDS/Ost (1990-1994) | D4: Revolutionary May 1st (joint march, 1990-1995) | E4: Revolutionary May 1st (18:00) | F4: Revolutionary May 1st (13:00) | G4: PDS/Ost (1995-2002) | H4: EuroMayDay | I4: Anti-Nazi counter-demonstration | J4: Neo-nazi/far right | K4: MyFest Kreuzberg (festival) | L4: Mariannenplatzfest (festival, since 2003 part of MyFest) | M4: MyGruni | N4: Total | O4: Total-trade union
A5: 1990 | B5: =IFERROR(__xludf.DUMMYFUNCTION("FILTER('Sources - Averages (Berlin)'!$G$5:$G$156,'Sources - Averages (Berlin)'!$A$5:$A$156=B$4,'Sources - Averages (Berlin)'!$B$5:$B$156=$A5)"),56666.666666666664) -> 56666.667 | C5: =IFERROR(__xludf.DUMMYFUNCTION("FILTER('Sources - Averages (Berlin)'!$G$5:$G$156,'Sources - Averages (Berlin)'!$A$5:$A$156=""PDS/Ost"",'Sources - Averages (Berlin)'!$B$5:$B$156=$A5)"),15500.0) -> 15500 | D5: =IFERROR(__xludf.DUMMYFUNCTION("FILTER('Sources - Averages (Berlin)'!$G$5:$G$156,'Sources - Averages (Berlin)'!$A$5:$A$156=D$4,'Sources - Averages (Berlin)'!$B$5:$B$156=$A5)"),12500.0) -> 12500 | N5: {=SUM(B5:M5)} -> 84666.667 | O5: =N5-B5 -> 28000
A6: 1991 | B6: =IFERROR(__xludf.DUMMYFUNCTION("FILTER('Sources - Averages (Berlin)'!$G$5:$G$156,'Sources - Averages (Berlin)'!$A$5:$A$156=B$4,'Sources - Averages (Berlin)'!$B$5:$B$156=A6)"),10000.0) -> 10000 | D6: =IFERROR(__xludf.DUMMYFUNCTION("FILTER('Sources - Averages (Berlin)'!$G$5:$G$156,'Sources - Averages (Berlin)'!$A$5:$A$156=D$4,'Sources - Averages (Berlin)'!$B$5:$B$156=$A6)"),12666.666666666666) -> 12666.667 | N6: {=SUM(B6:M6)} -> 22666.667 | O6: =N6-B6 -> 12666.667
A7: 1992 | B7: =IFERROR(__xludf.DUMMYFUNCTION("FILTER('Sources - Averages (Berlin)'!$G$5:$G$156,'Sources - Averages (Berlin)'!$A$5:$A$156=B$4,'Sources - Averages (Berlin)'!$B$5:$B$156=A7)"),23000.0) -> 23000 | C7: =IFERROR(__xludf.DUMMYFUNCTION("FILTER('Sources - Averages (Berlin)'!$G$5:$G$156,'Sources - Averages (Berlin)'!$A$5:$A$156=""PDS/Ost"",'Sources - Averages (Berlin)'!$B$5:$B$156=$A7)"),6000.0) -> 6000 | D7: =IFERROR(__xludf.DUMMYFUNCTION("FILTER('Sources - Averages (Berlin)'!$G$5:$G$156,'Sources - Averages (Berlin)'!$A$5:$A$156=D$4,'Sources - Averages (Berlin)'!$B$5:$B$156=$A7)"),12000.0) -> 12000 | I7: =IFERROR(__xludf.DUMMYFUNCTION("FILTER('Sources - Averages (Berlin)'!$G$5:$G$156,'Sources - Averages (Berlin)'!$A$5:$A$156=I$4,'Sources - Averages (Berlin)'!$B$5:$B$156=$A7)"),200.0) -> 200 | J7: =IFERROR(__xludf.DUMMYFUNCTION("FILTER('Sources - Averages (Berlin)'!$G$5:$G$156,'Sources - Averages (Berlin)'!$A$5:$A$156=J$4,'Sources - Averages (Berlin)'!$B$5:$B$156=$A7)"),50.0) -> 50 | N7: {=SUM(B7:M7)} -> 41250 | O7: =N7-B7 -> 18250
A8: 1993 | B8: =IFERROR(__xludf.DUMMYFUNCTION("FILTER('Sources - Averages (Berlin)'!$G$5:$G$156,'Sources - Averages (Berlin)'!$A$5:$A$156=B$4,'Sources - Averages (Berlin)'!$B$5:$B$156=A8)"),16666.666666666668) -> 16666.667 | C8: =IFERROR(__xludf.DUMMYFUNCTION("FILTER('Sources - Averages (Berlin)'!$G$5:$G$156,'Sources - Averages (Berlin)'!$A$5:$A$156=""PDS/Ost"",'Sources - Averages (Berlin)'!$B$5:$B$156=$A8)"),6000.0) -> 6000 | D8: =IFERROR(__xludf.DUMMYFUNCTION("FILTER('Sources - Averages (Berlin)'!$G$5:$G$156,'Sources - Averages (Berlin)'!$A$5:$A$156=D$4,'Sources - Averages (Berlin)'!$B$5:$B$156=$A8)"),7750.0) -> 7750 | J8: =IFERROR(__xludf.DUMMYFUNCTION("FILTER('Sources - Averages (Berlin)'!$G$5:$G$156,'Sources - Averages (Berlin)'!$A$5:$A$156=J$4,'Sources - Averages (Berlin)'!$B$5:$B$156=$A8)"),100.0) -> 100 | N8: {=SUM(B8:M8)} -> 30516.667 | O8: =N8-B8 -> 13850
A9: 1994 | B9: =IFERROR(__xludf.DUMMYFUNCTION("FILTER('Sources - Averages (Berlin)'!$G$5:$G$156,'Sources - Averages (Berlin)'!$A$5:$A$156=B$4,'Sources - Averages (Berlin)'!$B$5:$B$156=A9)"),6000.0) -> 6000 | C9: =IFERROR(__xludf.DUMMYFUNCTION("FILTER('Sources - Averages (Berlin)'!$G$5:$G$156,'Sources - Averages (Berlin)'!$A$5:$A$156=""PDS/Ost"",'Sources - Averages (Berlin)'!$B$5:$B$156=$A9)"),1000.0) -> 1000 | D9: =IFERROR(__xludf.DUMMYFUNCTION("FILTER('Sources - Averages (Berlin)'!$G$5:$G$156,'Sources - Averages (Berlin)'!$A$5:$A$156=D$4,'Sources - Averages (Berlin)'!$B$5:$B$156=$A9)"),900.0) -> 900 | I9: =IFERROR(__xludf.DUMMYFUNCTION("FILTER('Sources - Averages (Berlin)'!$G$5:$G$156,'Sources - Averages (Berlin)'!$A$5:$A$156=I$4,'Sources - Averages (Berlin)'!$B$5:$B$156=$A9)"),450.0) -> 450 | J9: =IFERROR(__xludf.DUMMYFUNCTION("FILTER('Sources - Averages (Berlin)'!$G$5:$G$156,'Sources - Averages (Berlin)'!$A$5:$A$156=J$4,'Sources - Averages (Berlin)'!$B$5:$B$156=$A9)"),5.0) -> 5 | N9: {=SUM(B9:M9)} -> 8355 | O9: =N9-B9 -> 2355
A10: 1995 | B10: =IFERROR(__xludf.DUMMYFUNCTION("FILTER('Sources - Averages (Berlin)'!$G$5:$G$156,'Sources - Averages (Berlin)'!$A$5:$A$156=B$4,'Sources - Averages (Berlin)'!$B$5:$B$156=A10)"),7400.0) -> 7400 | D10: =IFERROR(__xludf.DUMMYFUNCTION("FILTER('Sources - Averages (Berlin)'!$G$5:$G$156,'Sources - Averages (Berlin)'!$A$5:$A$156=D$4,'Sources - Averages (Berlin)'!$B$5:$B$156=$A10)"),2250.0) -> 2250 | G10: =IFERROR(__xludf.DUMMYFUNCTION("FILTER('Sources - Averages (Berlin)'!$G$5:$G$156,'Sources - Averages (Berlin)'!$A$5:$A$156=""PDS/Ost"",'Sources - Averages (Berlin)'!$B$5:$B$156=$A10)"),1600.0) -> 1600 | N10: {=SUM(B10:M10)} -> 11250 | O10: =N10-B10 -> 3850
A11: 1996 | B11: =IFERROR(__xludf.DUMMYFUNCTION("FILTER('Sources - Averages (Berlin)'!$G$5:$G$156,'Sources - Averages (Berlin)'!$A$5:$A$156=B$4,'Sources - Averages (Berlin)'!$B$5:$B$156=A11)"),16666.666666666668) -> 16666.667 | E11: =IFERROR(__xludf.DUMMYFUNCTION("FILTER('Sources - Averages (Berlin)'!$G$5:$G$156,'Sources - Averages (Berlin)'!$A$5:$A$156=E$4,'Sources - Averages (Berlin)'!$B$5:$B$156=$A11)"),10000.0) -> 10000 | F11: =IFERROR(__xludf.DUMMYFUNCTION("FILTER('Sources - Averages (Berlin)'!$G$5:$G$156,'Sources - Averages (Berlin)'!$A$5:$A$156=F$4,'Sources - Averages (Berlin)'!$B$5:$B$156=$A11)"),3000.0) -> 3000 | G11: =IFERROR(__xludf.DUMMYFUNCTION("FILTER('Sources - Averages (Berlin)'!$G$5:$G$156,'Sources - Averages (Berlin)'!$A$5:$A$156=""PDS/Ost"",'Sources - Averages (Berlin)'!$B$5:$B$156=$A11)"),2200.0) -> 2200 | I11: =IFERROR(__xludf.DUMMYFUNCTION("FILTER('Sources - Averages (Berlin)'!$G$5:$G$156,'Sources - Averages (Berlin)'!$A$5:$A$156=I$4,'Sources - Averages (Berlin)'!$B$5:$B$156=$A11)"),40.0) -> 40 | J11: =IFERROR(__xludf.DUMMYFUNCTION("FILTER('Sources - Averages (Berlin)'!$G$5:$G$156,'Sources - Averages (Berlin)'!$A$5:$A$156=J$4,'Sources - Averages (Berlin)'!$B$5:$B$156=$A11)"),350.0) -> 350 | N11: {=SUM(B11:M11)} -> 32256.667 | O11: =N11-B11 -> 15590
A12: 1997 | B12: =IFERROR(__xludf.DUMMYFUNCTION("FILTER('Sources - Averages (Berlin)'!$G$5:$G$156,'Sources - Averages (Berlin)'!$A$5:$A$156=B$4,'Sources - Averages (Berlin)'!$B$5:$B$156=A12)"),9500.0) -> 9500 | E12: =IFERROR(__xludf.DUMMYFUNCTION("FILTER('Sources - Averages (Berlin)'!$G$5:$G$156,'Sources - Averages (Berlin)'!$A$5:$A$156=E$4,'Sources - Averages (Berlin)'!$B$5:$B$156=$A12)"),9000.0) -> 9000 | F12: =IFERROR(__xludf.DUMMYFUNCTION("FILTER('Sources - Averages (Berlin)'!$G$5:$G$156,'Sources - Averages (Berlin)'!$A$5:$A$156=F$4,'Sources - Averages (Berlin)'!$B$5:$B$156=$A12)"),2000.0) -> 2000 | G12: =IFERROR(__xludf.DUMMYFUNCTION("FILTER('Sources - Averages (Berlin)'!$G$5:$G$156,'Sources - Averages (Berlin)'!$A$5:$A$156=""PDS/Ost"",'Sources - Averages (Berlin)'!$B$5:$B$156=$A12)"),7333.333333333333) -> 7333.3333 | N12: {=SUM(B12:M12)} -> 27833.333 | O12: =N12-B12 -> 18333.333
A13: 1998 | B13: =IFERROR(__xludf.DUMMYFUNCTION("FILTER('Sources - Averages (Berlin)'!$G$5:$G$156,'Sources - Averages (Berlin)'!$A$5:$A$156=B$4,'Sources - Averages (Berlin)'!$B$5:$B$156=A13)"),13875.0) -> 13875 | E13: =IFERROR(__xludf.DUMMYFUNCTION("FILTER('Sources - Averages (Berlin)'!$G$5:$G$156,'Sources - Averages (Berlin)'!$A$5:$A$156=E$4,'Sources - Averages (Berlin)'!$B$5:$B$156=$A13)"),6666.666666666667) -> 6666.6667 | F13: =IFERROR(__xludf.DUMMYFUNCTION("FILTER('Sources - Averages (Berlin)'!$G$5:$G$156,'Sources - Averages (Berlin)'!$A$5:$A$156=F$4,'Sources - Averages (Berlin)'!$B$5:$B$156=$A13)"),1750.0) -> 1750 | G13: =IFERROR(__xludf.DUMMYFUNCTION("FILTER('Sources - Averages (Berlin)'!$G$5:$G$156,'Sources - Averages (Berlin)'!$A$5:$A$156=""PDS/Ost"",'Sources - Averages (Berlin)'!$B$5:$B$156=$A13)"),6500.0) -> 6500 | L13: =IFERROR(__xludf.DUMMYFUNCTION("FILTER('Sources - Averages (Berlin)'!$G$5:$G$156,'Sources - Averages (Berlin)'!$A$5:$A$156=L$4,'Sources - Averages (Berlin)'!$B$5:$B$156=$A13)"),1500.0) -> 1500 | N13: {=SUM(B13:M13)} -> 30291.667 | O13: =N13-B13 -> 16416.667
A14: 1999 | B14: =IFERROR(__xludf.DUMMYFUNCTION("FILTER('Sources - Averages (Berlin)'!$G$5:$G$156,'Sources - Averages (Berlin)'!$A$5:$A$156=B$4,'Sources - Averages (Berlin)'!$B$5:$B$156=A14)"),10400.0) -> 10400 | E14: =IFERROR(__xludf.DUMMYFUNCTION("FILTER('Sources - Averages (Berlin)'!$G$5:$G$156,'Sources - Averages (Berlin)'!$A$5:$A$156=E$4,'Sources - Averages (Berlin)'!$B$5:$B$156=$A14)"),14000.0) -> 14000 | F14: =IFERROR(__xludf.DUMMYFUNCTION("FILTER('Sources - Averages (Berlin)'!$G$5:$G$156,'Sources - Averages (Berlin)'!$A$5:$A$156=F$4,'Sources - Averages (Berlin)'!$B$5:$B$156=$A14)"),1500.0) -> 1500 | G14: =IFERROR(__xludf.DUMMYFUNCTION("FILTER('Sources - Averages (Berlin)'!$G$5:$G$156,'Sources - Averages (Berlin)'!$A$5:$A$156=""PDS/Ost"",'Sources - Averages (Berlin)'!$B$5:$B$156=$A14)"),10000.0) -> 10000 | N14: {=SUM(B14:M14)} -> 35900 | O14: =N14-B14 -> 25500
A15: 2000 | B15: =IFERROR(__xludf.DUMMYFUNCTION("FILTER('Sources - Averages (Berlin)'!$G$5:$G$156,'Sources - Averages (Berlin)'!$A$5:$A$156=B$4,'Sources - Averages (Berlin)'!$B$5:$B$156=A15)"),11166.666666666666) -> 11166.667 | E15: =IFERROR(__xludf.DUMMYFUNCTION("FILTER('Sources - Averages (Berlin)'!$G$5:$G$156,'Sources - Averages (Berlin)'!$A$5:$A$156=E$4,'Sources - Averages (Berlin)'!$B$5:$B$156=$A15)"),13333.333333333334) -> 13333.333 | F15: =IFERROR(__xludf.DUMMYFUNCTION("FILTER('Sources - Averages (Berlin)'!$G$5:$G$156,'Sources - Averages (Berlin)'!$A$5:$A$156=F$4,'Sources - Averages (Berlin)'!$B$5:$B$156=$A15)"),1266.6666666666667) -> 1266.6667 | G15: =IFERROR(__xludf.DUMMYFUNCTION("FILTER('Sources - Averages (Berlin)'!$G$5:$G$156,'Sources - Averages (Berlin)'!$A$5:$A$156=""PDS/Ost"",'Sources - Averages (Berlin)'!$B$5:$B$156=$A15)"),3666.6666666666665) -> 3666.6667 | I15: =IFERROR(__xludf.DUMMYFUNCTION("FILTER('Sources - Averages (Berlin)'!$G$5:$G$156,'Sources - Averages (Berlin)'!$A$5:$A$156=I$4,'Sources - Averages (Berlin)'!$B$5:$B$156=$A15)"),10000.0) -> 10000 | J15: =IFERROR(__xludf.DUMMYFUNCTION("FILTER('Sources - Averages (Berlin)'!$G$5:$G$156,'Sources - Averages (Berlin)'!$A$5:$A$156=J$4,'Sources - Averages (Berlin)'!$B$5:$B$156=$A15)"),1000.0) -> 1000 | L15: =IFERROR(__xludf.DUMMYFUNCTION("FILTER('Sources - Averages (Berlin)'!$G$5:$G$156,'Sources - Averages (Berlin)'!$A$5:$A$156=L$4,'Sources - Averages (Berlin)'!$B$5:$B$156=$A15)"),5000.0) -> 5000 | N15: {=SUM(B15:M15)} -> 45433.333 | O15: =N15-B15 -> 34266.667
A16: 2001 | B16: =IFERROR(__xludf.DUMMYFUNCTION("FILTER('Sources - Averages (Berlin)'!$G$5:$G$156,'Sources - Averages (Berlin)'!$A$5:$A$156=B$4,'Sources - Averages (Berlin)'!$B$5:$B$156=A16)"),16833.333333333332) -> 16833.333 | E16: =IFERROR(__xludf.DUMMYFUNCTION("FILTER('Sources - Averages (Berlin)'!$G$5:$G$156,'Sources - Averages (Berlin)'!$A$5:$A$156=E$4,'Sources - Averages (Berlin)'!$B$5:$B$156=$A16)"),5500.0) -> 5500 | F16: =IFERROR(__xludf.DUMMYFUNCTION("FILTER('Sources - Averages (Berlin)'!$G$5:$G$156,'Sources - Averages (Berlin)'!$A$5:$A$156=F$4,'Sources - Averages (Berlin)'!$B$5:$B$156=$A16)"),2250.0) -> 2250 | G16: =IFERROR(__xludf.DUMMYFUNCTION("FILTER('Sources - Averages (Berlin)'!$G$5:$G$156,'Sources - Averages (Berlin)'!$A$5:$A$156=""PDS/Ost"",'Sources - Averages (Berlin)'!$B$5:$B$156=$A16)"),7250.0) -> 7250 | I16: =IFERROR(__xludf.DUMMYFUNCTION("FILTER('Sources - Averages (Berlin)'!$G$5:$G$156,'Sources - Averages (Berlin)'!$A$5:$A$156=I$4,'Sources - Averages (Berlin)'!$B$5:$B$156=$A16)"),475.0) -> 475 | J16: =IFERROR(__xludf.DUMMYFUNCTION("FILTER('Sources - Averages (Berlin)'!$G$5:$G$156,'Sources - Averages (Berlin)'!$A$5:$A$156=J$4,'Sources - Averages (Berlin)'!$B$5:$B$156=$A16)"),100.0) -> 100 | L16: =IFERROR(__xludf.DUMMYFUNCTION("FILTER('Sources - Averages (Berlin)'!$G$5:$G$156,'Sources - Averages (Berlin)'!$A$5:$A$156=L$4,'Sources - Averages (Berlin)'!$B$5:$B$156=$A16)"),5000.0) -> 5000 | N16: {=SUM(B16:M16)} -> 37408.333 | O16: =N16-B16 -> 20575
A17: 2002 | B17: =IFERROR(__xludf.DUMMYFUNCTION("FILTER('Sources - Averages (Berlin)'!$G$5:$G$156,'Sources - Averages (Berlin)'!$A$5:$A$156=B$4,'Sources - Averages (Berlin)'!$B$5:$B$156=A17)"),13500.0) -> 13500 | E17: =IFERROR(__xludf.DUMMYFUNCTION("FILTER('Sources - Averages (Berlin)'!$G$5:$G$156,'Sources - Averages (Berlin)'!$A$5:$A$156=E$4,'Sources - Averages (Berlin)'!$B$5:$B$156=$A17)"),9500.0) -> 9500 | F17: =IFERROR(__xludf.DUMMYFUNCTION("FILTER('Sources - Averages (Berlin)'!$G$5:$G$156,'Sources - Averages (Berlin)'!$A$5:$A$156=F$4,'Sources - Averages (Berlin)'!$B$5:$B$156=$A17)"),4000.0) -> 4000 | G17: =IFERROR(__xludf.DUMMYFUNCTION("FILTER('Sources - Averages (Berlin)'!$G$5:$G$156,'Sources - Averages (Berlin)'!$A$5:$A$156=""PDS/Ost"",'Sources - Averages (Berlin)'!$B$5:$B$156=$A17)"),2250.0) -> 2250 | I17: =IFERROR(__xludf.DUMMYFUNCTION("FILTER('Sources - Averages (Berlin)'!$G$5:$G$156,'Sources - Averages (Berlin)'!$A$5:$A$156=I$4,'Sources - Averages (Berlin)'!$B$5:$B$156=$A17)"),1000.0) -> 1000 | J17: =IFERROR(__xludf.DUMMYFUNCTION("FILTER('Sources - Averages (Berlin)'!$G$5:$G$156,'Sources - Averages (Berlin)'!$A$5:$A$156=J$4,'Sources - Averages (Berlin)'!$B$5:$B$156=$A17)"),700.0) -> 700 | N17: {=SUM(B17:M17)} -> 30950 | O17: =N17-B17 -> 17450
A18: 2003 | B18: =IFERROR(__xludf.DUMMYFUNCTION("FILTER('Sources - Averages (Berlin)'!$G$5:$G$156,'Sources - Averages (Berlin)'!$A$5:$A$156=B$4,'Sources - Averages (Berlin)'!$B$5:$B$156=A18)"),13500.0) -> 13500 | E18: =IFERROR(__xludf.DUMMYFUNCTION("FILTER('Sources - Averages (Berlin)'!$G$5:$G$156,'Sources - Averages (Berlin)'!$A$5:$A$156=E$4,'Sources - Averages (Berlin)'!$B$5:$B$156=$A18)"),3500.0) -> 3500 | F18: =IFERROR(__xludf.DUMMYFUNCTION("FILTER('Sources - Averages (Berlin)'!$G$5:$G$156,'Sources - Averages (Berlin)'!$A$5:$A$156=F$4,'Sources - Averages (Berlin)'!$B$5:$B$156=$A18)"),6750.0) -> 6750 | I18: =IFERROR(__xludf.DUMMYFUNCTION("FILTER('Sources - Averages (Berlin)'!$G$5:$G$156,'Sources - Averages (Berlin)'!$A$5:$A$156=I$4,'Sources - Averages (Berlin)'!$B$5:$B$156=$A18)"),250.0) -> 250 | J18: =IFERROR(__xludf.DUMMYFUNCTION("FILTER('Sources - Averages (Berlin)'!$G$5:$G$156,'Sources - Averages (Berlin)'!$A$5:$A$156=J$4,'Sources - Averages (Berlin)'!$B$5:$B$156=$A18)"),1675.0) -> 1675 | K18: =IFERROR(__xludf.DUMMYFUNCTION("FILTER('Sources - Averages (Berlin)'!$G$5:$G$156,'Sources - Averages (Berlin)'!$A$5:$A$156=K$4,'Sources - Averages (Berlin)'!$B$5:$B$156=$A18)"),20000.0) -> 20000 | L18: =IFERROR(__xludf.DUMMYFUNCTION("FILTER('Sources - Averages (Berlin)'!$G$5:$G$156,'Sources - Averages (Berlin)'!$A$5:$A$156=L$4,'Sources - Averages (Berlin)'!$B$5:$B$156=$A18)"),20000.0) -> 20000 | N18: {=SUM(B18:M18)} -> 65675 | O18: =N18-B18 -> 52175
A19: 2004 | B19: =IFERROR(__xludf.DUMMYFUNCTION("FILTER('Sources - Averages (Berlin)'!$G$5:$G$156,'Sources - Averages (Berlin)'!$A$5:$A$156=B$4,'Sources - Averages (Berlin)'!$B$5:$B$156=A19)"),18500.0) -> 18500 | E19: =IFERROR(__xludf.DUMMYFUNCTION("FILTER('Sources - Averages (Berlin)'!$G$5:$G$156,'Sources - Averages (Berlin)'!$A$5:$A$156=E$4,'Sources - Averages (Berlin)'!$B$5:$B$156=$A19)"),3500.0) -> 3500 | F19: =IFERROR(__xludf.DUMMYFUNCTION("FILTER('Sources - Averages (Berlin)'!$G$5:$G$156,'Sources - Averages (Berlin)'!$A$5:$A$156=F$4,'Sources - Averages (Berlin)'!$B$5:$B$156=$A19)"),5000.0) -> 5000 | I19: =IFERROR(__xludf.DUMMYFUNCTION("FILTER('Sources - Averages (Berlin)'!$G$5:$G$156,'Sources - Averages (Berlin)'!$A$5:$A$156=I$4,'Sources - Averages (Berlin)'!$B$5:$B$156=$A19)"),3400.0) -> 3400 | J19: =IFERROR(__xludf.DUMMYFUNCTION("FILTER('Sources - Averages (Berlin)'!$G$5:$G$156,'Sources - Averages (Berlin)'!$A$5:$A$156=J$4,'Sources - Averages (Berlin)'!$B$5:$B$156=$A19)"),2300.0) -> 2300 | K19: =IFERROR(__xludf.DUMMYFUNCTION("FILTER('Sources - Averages (Berlin)'!$G$5:$G$156,'Sources - Averages (Berlin)'!$A$5:$A$156=K$4,'Sources - Averages (Berlin)'!$B$5:$B$156=$A19)"),30000.0) -> 30000 | N19: {=SUM(B19:M19)} -> 62700 | O19: =N19-B19 -> 44200
A20: 2005 | B20: =IFERROR(__xludf.DUMMYFUNCTION("FILTER('Sources - Averages (Berlin)'!$G$5:$G$156,'Sources - Averages (Berlin)'!$A$5:$A$156=B$4,'Sources - Averages (Berlin)'!$B$5:$B$156=A20)"),10500.0) -> 10500 | E20: =IFERROR(__xludf.DUMMYFUNCTION("FILTER('Sources - Averages (Berlin)'!$G$5:$G$156,'Sources - Averages (Berlin)'!$A$5:$A$156=E$4,'Sources - Averages (Berlin)'!$B$5:$B$156=$A20)"),0.0) -> 0 | F20: =IFERROR(__xludf.DUMMYFUNCTION("FILTER('Sources - Averages (Berlin)'!$G$5:$G$156,'Sources - Averages (Berlin)'!$A$5:$A$156=F$4,'Sources - Averages (Berlin)'!$B$5:$B$156=$A20)"),500.0) -> 500 | K20: =IFERROR(__xludf.DUMMYFUNCTION("FILTER('Sources - Averages (Berlin)'!$G$5:$G$156,'Sources - Averages (Berlin)'!$A$5:$A$156=K$4,'Sources - Averages (Berlin)'!$B$5:$B$156=$A20)"),15000.0) -> 15000 | N20: {=SUM(B20:M20)} -> 26000 | O20: =N20-B20 -> 15500
A21: 2006 | B21: =IFERROR(__xludf.DUMMYFUNCTION("FILTER('Sources - Averages (Berlin)'!$G$5:$G$156,'Sources - Averages (Berlin)'!$A$5:$A$156=B$4,'Sources - Averages (Berlin)'!$B$5:$B$156=A21)"),13500.0) -> 13500 | E21: =IFERROR(__xludf.DUMMYFUNCTION("FILTER('Sources - Averages (Berlin)'!$G$5:$G$156,'Sources - Averages (Berlin)'!$A$5:$A$156=E$4,'Sources - Averages (Berlin)'!$B$5:$B$156=$A21)"),0.0) -> 0 | F21: =IFERROR(__xludf.DUMMYFUNCTION("FILTER('Sources - Averages (Berlin)'!$G$5:$G$156,'Sources - Averages (Berlin)'!$A$5:$A$156=F$4,'Sources - Averages (Berlin)'!$B$5:$B$156=$A21)"),50.0) -> 50 | H21: =IFERROR(__xludf.DUMMYFUNCTION("FILTER('Sources - Averages (Berlin)'!$G$5:$G$156,'Sources - Averages (Berlin)'!$A$5:$A$156=H$4,'Sources - Averages (Berlin)'!$B$5:$B$156=$A21)"),4000.0) -> 4000 | K21: =IFERROR(__xludf.DUMMYFUNCTION("FILTER('Sources - Averages (Berlin)'!$G$5:$G$156,'Sources - Averages (Berlin)'!$A$5:$A$156=K$4,'Sources - Averages (Berlin)'!$B$5:$B$156=$A21)"),11000.0) -> 11000 | N21: {=SUM(B21:M21)} -> 28550 | O21: =N21-B21 -> 15050
A22: 2007 | B22: =IFERROR(__xludf.DUMMYFUNCTION("FILTER('Sources - Averages (Berlin)'!$G$5:$G$156,'Sources - Averages (Berlin)'!$A$5:$A$156=B$4,'Sources - Averages (Berlin)'!$B$5:$B$156=A22)"),10500.0) -> 10500 | E22: =IFERROR(__xludf.DUMMYFUNCTION("FILTER('Sources - Averages (Berlin)'!$G$5:$G$156,'Sources - Averages (Berlin)'!$A$5:$A$156=E$4,'Sources - Averages (Berlin)'!$B$5:$B$156=$A22)"),7666.666666666667) -> 7666.6667 | F22: =IFERROR(__xludf.DUMMYFUNCTION("FILTER('Sources - Averages (Berlin)'!$G$5:$G$156,'Sources - Averages (Berlin)'!$A$5:$A$156=F$4,'Sources - Averages (Berlin)'!$B$5:$B$156=$A22)"),900.0) -> 900 | H22: =IFERROR(__xludf.DUMMYFUNCTION("FILTER('Sources - Averages (Berlin)'!$G$5:$G$156,'Sources - Averages (Berlin)'!$A$5:$A$156=H$4,'Sources - Averages (Berlin)'!$B$5:$B$156=$A22)"),7000.0) -> 7000 | K22: =IFERROR(__xludf.DUMMYFUNCTION("FILTER('Sources - Averages (Berlin)'!$G$5:$G$156,'Sources - Averages (Berlin)'!$A$5:$A$156=K$4,'Sources - Averages (Berlin)'!$B$5:$B$156=$A22)"),42000.0) -> 42000 | N22: {=SUM(B22:M22)} -> 68066.667 | O22: =N22-B22 -> 57566.667
A23: 2008 | B23: =IFERROR(__xludf.DUMMYFUNCTION("FILTER('Sources - Averages (Berlin)'!$G$5:$G$156,'Sources - Averages (Berlin)'!$A$5:$A$156=B$4,'Sources - Averages (Berlin)'!$B$5:$B$156=A23)"),9125.0) -> 9125 | E23: =IFERROR(__xludf.DUMMYFUNCTION("FILTER('Sources - Averages (Berlin)'!$G$5:$G$156,'Sources - Averages (Berlin)'!$A$5:$A$156=E$4,'Sources - Averages (Berlin)'!$B$5:$B$156=$A23)"),11000.0) -> 11000 | F23: =IFERROR(__xludf.DUMMYFUNCTION("FILTER('Sources - Averages (Berlin)'!$G$5:$G$156,'Sources - Averages (Berlin)'!$A$5:$A$156=F$4,'Sources - Averages (Berlin)'!$B$5:$B$156=$A23)"),300.0) -> 300 | H23: =IFERROR(__xludf.DUMMYFUNCTION("FILTER('Sources - Averages (Berlin)'!$G$5:$G$156,'Sources - Averages (Berlin)'!$A$5:$A$156=H$4,'Sources - Averages (Berlin)'!$B$5:$B$156=$A23)"),6500.0) -> 6500 | K23: =IFERROR(__xludf.DUMMYFUNCTION("FILTER('Sources - Averages (Berlin)'!$G$5:$G$156,'Sources - Averages (Berlin)'!$A$5:$A$156=K$4,'Sources - Averages (Berlin)'!$B$5:$B$156=$A23)"),20000.0) -> 20000 | N23: {=SUM(B23:M23)} -> 46925 | O23: =N23-B23 -> 37800
A24: 2009 | B24: =IFERROR(__xludf.DUMMYFUNCTION("FILTER('Sources - Averages (Berlin)'!$G$5:$G$156,'Sources - Averages (Berlin)'!$A$5:$A$156=B$4,'Sources - Averages (Berlin)'!$B$5:$B$156=A24)"),13500.0) -> 13500 | E24: =IFERROR(__xludf.DUMMYFUNCTION("FILTER('Sources - Averages (Berlin)'!$G$5:$G$156,'Sources - Averages (Berlin)'!$A$5:$A$156=E$4,'Sources - Averages (Berlin)'!$B$5:$B$156=$A24)"),8500.0) -> 8500 | F24: =IFERROR(__xludf.DUMMYFUNCTION("FILTER('Sources - Averages (Berlin)'!$G$5:$G$156,'Sources - Averages (Berlin)'!$A$5:$A$156=F$4,'Sources - Averages (Berlin)'!$B$5:$B$156=$A24)"),300.0) -> 300 | H24: =IFERROR(__xludf.DUMMYFUNCTION("FILTER('Sources - Averages (Berlin)'!$G$5:$G$156,'Sources - Averages (Berlin)'!$A$5:$A$156=H$4,'Sources - Averages (Berlin)'!$B$5:$B$156=$A24)"),3500.0) -> 3500 | I24: =IFERROR(__xludf.DUMMYFUNCTION("FILTER('Sources - Averages (Berlin)'!$G$5:$G$156,'Sources - Averages (Berlin)'!$A$5:$A$156=I$4,'Sources - Averages (Berlin)'!$B$5:$B$156=$A24)"),3500.0) -> 3500 | J24: =IFERROR(__xludf.DUMMYFUNCTION("FILTER('Sources - Averages (Berlin)'!$G$5:$G$156,'Sources - Averages (Berlin)'!$A$5:$A$156=J$4,'Sources - Averages (Berlin)'!$B$5:$B$156=$A24)"),200.0) -> 200 | K24: =IFERROR(__xludf.DUMMYFUNCTION("FILTER('Sources - Averages (Berlin)'!$G$5:$G$156,'Sources - Averages (Berlin)'!$A$5:$A$156=K$4,'Sources - Averages (Berlin)'!$B$5:$B$156=$A24)"),35000.0) -> 35000 | N24: {=SUM(B24:M24)} -> 64500 | O24: =N24-B24 -> 51000
A25: 2010 | B25: =IFERROR(__xludf.DUMMYFUNCTION("FILTER('Sources - Averages (Berlin)'!$G$5:$G$156,'Sources - Averages (Berlin)'!$A$5:$A$156=B$4,'Sources - Averages (Berlin)'!$B$5:$B$156=A25)"),9750.0) -> 9750 | E25: =IFERROR(__xludf.DUMMYFUNCTION("FILTER('Sources - Averages (Berlin)'!$G$5:$G$156,'Sources - Averages (Berlin)'!$A$5:$A$156=E$4,'Sources - Averages (Berlin)'!$B$5:$B$156=$A25)"),12500.0) -> 12500 | F25: =IFERROR(__xludf.DUMMYFUNCTION("FILTER('Sources - Averages (Berlin)'!$G$5:$G$156,'Sources - Averages (Berlin)'!$A$5:$A$156=F$4,'Sources - Averages (Berlin)'!$B$5:$B$156=$A25)"),50.0) -> 50 | I25: =IFERROR(__xludf.DUMMYFUNCTION("FILTER('Sources - Averages (Berlin)'!$G$5:$G$156,'Sources - Averages (Berlin)'!$A$5:$A$156=I$4,'Sources - Averages (Berlin)'!$B$5:$B$156=$A25)"),10000.0) -> 10000 | J25: =IFERROR(__xludf.DUMMYFUNCTION("FILTER('Sources - Averages (Berlin)'!$G$5:$G$156,'Sources - Averages (Berlin)'!$A$5:$A$156=J$4,'Sources - Averages (Berlin)'!$B$5:$B$156=$A25)"),700.0) -> 700 | K25: =IFERROR(__xludf.DUMMYFUNCTION("FILTER('Sources - Averages (Berlin)'!$G$5:$G$156,'Sources - Averages (Berlin)'!$A$5:$A$156=K$4,'Sources - Averages (Berlin)'!$B$5:$B$156=$A25)"),29000.0) -> 29000 | N25: {=SUM(B25:M25)} -> 62000 | O25: =N25-B25 -> 52250
A26: 2011 | B26: =IFERROR(__xludf.DUMMYFUNCTION("FILTER('Sources - Averages (Berlin)'!$G$5:$G$156,'Sources - Averages (Berlin)'!$A$5:$A$156=B$4,'Sources - Averages (Berlin)'!$B$5:$B$156=A26)"),11500.0) -> 11500 | E26: =IFERROR(__xludf.DUMMYFUNCTION("FILTER('Sources - Averages (Berlin)'!$G$5:$G$156,'Sources - Averages (Berlin)'!$A$5:$A$156=E$4,'Sources - Averages (Berlin)'!$B$5:$B$156=$A26)"),11333.333333333334) -> 11333.333 | K26: =IFERROR(__xludf.DUMMYFUNCTION("FILTER('Sources - Averages (Berlin)'!$G$5:$G$156,'Sources - Averages (Berlin)'!$A$5:$A$156=K$4,'Sources - Averages (Berlin)'!$B$5:$B$156=$A26)"),27000.0) -> 27000 | N26: {=SUM(B26:M26)} -> 49833.333 | O26: =N26-B26 -> 38333.333
A27: 2012 | B27: =IFERROR(__xludf.DUMMYFUNCTION("FILTER('Sources - Averages (Berlin)'!$G$5:$G$156,'Sources - Averages (Berlin)'!$A$5:$A$156=B$4,'Sources - Averages (Berlin)'!$B$5:$B$156=A27)"),12625.0) -> 12625 | E27: =IFERROR(__xludf.DUMMYFUNCTION("FILTER('Sources - Averages (Berlin)'!$G$5:$G$156,'Sources - Averages (Berlin)'!$A$5:$A$156=E$4,'Sources - Averages (Berlin)'!$B$5:$B$156=$A27)"),18500.0) -> 18500 | K27: =IFERROR(__xludf.DUMMYFUNCTION("FILTER('Sources - Averages (Berlin)'!$G$5:$G$156,'Sources - Averages (Berlin)'!$A$5:$A$156=K$4,'Sources - Averages (Berlin)'!$B$5:$B$156=$A27)"),31333.333333333332) -> 31333.333 | N27: {=SUM(B27:M27)} -> 62458.333 | O27: =N27-B27 -> 49833.333
A28: 2013 | B28: =IFERROR(__xludf.DUMMYFUNCTION("FILTER('Sources - Averages (Berlin)'!$G$5:$G$156,'Sources - Averages (Berlin)'!$A$5:$A$156=B$4,'Sources - Averages (Berlin)'!$B$5:$B$156=A28)"),9750.0) -> 9750 | E28: =IFERROR(__xludf.DUMMYFUNCTION("FILTER('Sources - Averages (Berlin)'!$G$5:$G$156,'Sources - Averages (Berlin)'!$A$5:$A$156=E$4,'Sources - Averages (Berlin)'!$B$5:$B$156=$A28)"),11666.666666666666) -> 11666.667 | I28: =IFERROR(__xludf.DUMMYFUNCTION("FILTER('Sources - Averages (Berlin)'!$G$5:$G$156,'Sources - Averages (Berlin)'!$A$5:$A$156=I$4,'Sources - Averages (Berlin)'!$B$5:$B$156=$A28)"),2000.0) -> 2000 | J28: =IFERROR(__xludf.DUMMYFUNCTION("FILTER('Sources - Averages (Berlin)'!$G$5:$G$156,'Sources - Averages (Berlin)'!$A$5:$A$156=J$4,'Sources - Averages (Berlin)'!$B$5:$B$156=$A28)"),300.0) -> 300 | K28: =IFERROR(__xludf.DUMMYFUNCTION("FILTER('Sources - Averages (Berlin)'!$G$5:$G$156,'Sources - Averages (Berlin)'!$A$5:$A$156=K$4,'Sources - Averages (Berlin)'!$B$5:$B$156=$A28)"),40000.0) -> 40000 | N28: {=SUM(B28:M28)} -> 63716.667 | O28: =N28-B28 -> 53966.667
A29: 2014 | B29: =IFERROR(__xludf.DUMMYFUNCTION("FILTER('Sources - Averages (Berlin)'!$G$5:$G$156,'Sources - Averages (Berlin)'!$A$5:$A$156=B$4,'Sources - Averages (Berlin)'!$B$5:$B$156=A29)"),10000.0) -> 10000 | E29: =IFERROR(__xludf.DUMMYFUNCTION("FILTER('Sources - Averages (Berlin)'!$G$5:$G$156,'Sources - Averages (Berlin)'!$A$5:$A$156=E$4,'Sources - Averages (Berlin)'!$B$5:$B$156=$A29)"),22000.0) -> 22000 | K29: =IFERROR(__xludf.DUMMYFUNCTION("FILTER('Sources - Averages (Berlin)'!$G$5:$G$156,'Sources - Averages (Berlin)'!$A$5:$A$156=K$4,'Sources - Averages (Berlin)'!$B$5:$B$156=$A29)"),40000.0) -> 40000 | N29: {=SUM(B29:M29)} -> 72000 | O29: =N29-B29 -> 62000
A30: 2015 | B30: =IFERROR(__xludf.DUMMYFUNCTION("FILTER('Sources - Averages (Berlin)'!$G$5:$G$156,'Sources - Averages (Berlin)'!$A$5:$A$156=B$4,'Sources - Averages (Berlin)'!$B$5:$B$156=A30)"),15000.0) -> 15000 | E30: =IFERROR(__xludf.DUMMYFUNCTION("FILTER('Sources - Averages (Berlin)'!$G$5:$G$156,'Sources - Averages (Berlin)'!$A$5:$A$156=E$4,'Sources - Averages (Berlin)'!$B$5:$B$156=$A30)"),25500.0) -> 25500 | I30: =IFERROR(__xludf.DUMMYFUNCTION("FILTER('Sources - Averages (Berlin)'!$G$5:$G$156,'Sources - Averages (Berlin)'!$A$5:$A$156=I$4,'Sources - Averages (Berlin)'!$B$5:$B$156=$A30)"),500.0) -> 500 | J30: =IFERROR(__xludf.DUMMYFUNCTION("FILTER('Sources - Averages (Berlin)'!$G$5:$G$156,'Sources - Averages (Berlin)'!$A$5:$A$156=J$4,'Sources - Averages (Berlin)'!$B$5:$B$156=$A30)"),50.0) -> 50 | K30: =IFERROR(__xludf.DUMMYFUNCTION("FILTER('Sources - Averages (Berlin)'!$G$5:$G$156,'Sources - Averages (Berlin)'!$A$5:$A$156=K$4,'Sources - Averages (Berlin)'!$B$5:$B$156=$A30)"),45000.0) -> 45000 | N30: {=SUM(B30:M30)} -> 86050 | O30: =N30-B30 -> 71050
A31: 2016 | B31: =IFERROR(__xludf.DUMMYFUNCTION("FILTER('Sources - Averages (Berlin)'!$G$5:$G$156,'Sources - Averages (Berlin)'!$A$5:$A$156=B$4,'Sources - Averages (Berlin)'!$B$5:$B$156=A31)"),14000.0) -> 14000 | E31: =IFERROR(__xludf.DUMMYFUNCTION("FILTER('Sources - Averages (Berlin)'!$G$5:$G$156,'Sources - Averages (Berlin)'!$A$5:$A$156=E$4,'Sources - Averages (Berlin)'!$B$5:$B$156=$A31)"),16500.0) -> 16500 | F31: =IFERROR(__xludf.DUMMYFUNCTION("FILTER('Sources - Averages (Berlin)'!$G$5:$G$156,'Sources - Averages (Berlin)'!$A$5:$A$156=F$4,'Sources - Averages (Berlin)'!$B$5:$B$156=$A31)"),250.0) -> 250 | I31: =IFERROR(__xludf.DUMMYFUNCTION("FILTER('Sources - Averages (Berlin)'!$G$5:$G$156,'Sources - Averages (Berlin)'!$A$5:$A$156=I$4,'Sources - Averages (Berlin)'!$B$5:$B$156=$A31)"),900.0) -> 900 | J31: =IFERROR(__xludf.DUMMYFUNCTION("FILTER('Sources - Averages (Berlin)'!$G$5:$G$156,'Sources - Averages (Berlin)'!$A$5:$A$156=J$4,'Sources - Averages (Berlin)'!$B$5:$B$156=$A31)"),50.0) -> 50 | K31: =IFERROR(__xludf.DUMMYFUNCTION("FILTER('Sources - Averages (Berlin)'!$G$5:$G$156,'Sources - Averages (Berlin)'!$A$5:$A$156=K$4,'Sources - Averages (Berlin)'!$B$5:$B$156=$A31)"),30000.0) -> 30000 | N31: {=SUM(B31:M31)} -> 61700 | O31: =N31-B31 -> 47700
A32: 2017 | B32: =IFERROR(__xludf.DUMMYFUNCTION("FILTER('Sources - Averages (Berlin)'!$G$5:$G$156,'Sources - Averages (Berlin)'!$A$5:$A$156=B$4,'Sources - Averages (Berlin)'!$B$5:$B$156=A32)"),14000.0) -> 14000 | E32: =IFERROR(__xludf.DUMMYFUNCTION("FILTER('Sources - Averages (Berlin)'!$G$5:$G$156,'Sources - Averages (Berlin)'!$A$5:$A$156=E$4,'Sources - Averages (Berlin)'!$B$5:$B$156=$A32)"),15000.0) -> 15000 | F32: =IFERROR(__xludf.DUMMYFUNCTION("FILTER('Sources - Averages (Berlin)'!$G$5:$G$156,'Sources - Averages (Berlin)'!$A$5:$A$156=F$4,'Sources - Averages (Berlin)'!$B$5:$B$156=$A32)"),250.0) -> 250 | I32: =IFERROR(__xludf.DUMMYFUNCTION("FILTER('Sources - Averages (Berlin)'!$G$5:$G$156,'Sources - Averages (Berlin)'!$A$5:$A$156=I$4,'Sources - Averages (Berlin)'!$B$5:$B$156=$A32)"),600.0) -> 600 | J32: =IFERROR(__xludf.DUMMYFUNCTION("FILTER('Sources - Averages (Berlin)'!$G$5:$G$156,'Sources - Averages (Berlin)'!$A$5:$A$156=J$4,'Sources - Averages (Berlin)'!$B$5:$B$156=$A32)"),50.0) -> 50 | K32: =IFERROR(__xludf.DUMMYFUNCTION("FILTER('Sources - Averages (Berlin)'!$G$5:$G$156,'Sources - Averages (Berlin)'!$A$5:$A$156=K$4,'Sources - Averages (Berlin)'!$B$5:$B$156=$A32)"),45000.0) -> 45000 | N32: {=SUM(B32:M32)} -> 74900 | O32: =N32-B32 -> 60900
A33: 2018 | B33: =IFERROR(__xludf.DUMMYFUNCTION("FILTER('Sources - Averages (Berlin)'!$G$5:$G$156,'Sources - Averages (Berlin)'!$A$5:$A$156=B$4,'Sources - Averages (Berlin)'!$B$5:$B$156=A33)"),9500.0) -> 9500 | E33: =IFERROR(__xludf.DUMMYFUNCTION("FILTER('Sources - Averages (Berlin)'!$G$5:$G$156,'Sources - Averages (Berlin)'!$A$5:$A$156=E$4,'Sources - Averages (Berlin)'!$B$5:$B$156=$A33)"),12500.0) -> 12500 | F33: =IFERROR(__xludf.DUMMYFUNCTION("FILTER('Sources - Averages (Berlin)'!$G$5:$G$156,'Sources - Averages (Berlin)'!$A$5:$A$156=F$4,'Sources - Averages (Berlin)'!$B$5:$B$156=$A33)"),200.0) -> 200 | J33: =IFERROR(__xludf.DUMMYFUNCTION("FILTER('Sources - Averages (Berlin)'!$G$5:$G$156,'Sources - Averages (Berlin)'!$A$5:$A$156=J$4,'Sources - Averages (Berlin)'!$B$5:$B$156=$A33)"),30.0) -> 30 | K33: =IFERROR(__xludf.DUMMYFUNCTION("FILTER('Sources - Averages (Berlin)'!$G$5:$G$156,'Sources - Averages (Berlin)'!$A$5:$A$156=K$4,'Sources - Averages (Berlin)'!$B$5:$B$156=$A33)"),52000.0) -> 52000 | M33: =IFERROR(__xludf.DUMMYFUNCTION("FILTER('Sources - Averages (Berlin)'!$G$5:$G$156,'Sources - Averages (Berlin)'!$A$5:$A$156=M$4,'Sources - Averages (Berlin)'!$B$5:$B$156=$A33)"),3250.0) -> 3250 | N33: {=SUM(B33:M33)} -> 77480 | O33: =N33-B33 -> 67980
A34: 2019 | B34: =IFERROR(__xludf.DUMMYFUNCTION("FILTER('Sources - Averages (Berlin)'!$G$5:$G$156,'Sources - Averages (Berlin)'!$A$5:$A$156=B$4,'Sources - Averages (Berlin)'!$B$5:$B$156=A34)"),13000.0) -> 13000 | E34: =IFERROR(__xludf.DUMMYFUNCTION("FILTER('Sources - Averages (Berlin)'!$G$5:$G$156,'Sources - Averages (Berlin)'!$A$5:$A$156=E$4,'Sources - Averages (Berlin)'!$B$5:$B$156=$A34)"),10000.0) -> 10000 | F34: =IFERROR(__xludf.DUMMYFUNCTION("FILTER('Sources - Averages (Berlin)'!$G$5:$G$156,'Sources - Averages (Berlin)'!$A$5:$A$156=F$4,'Sources - Averages (Berlin)'!$B$5:$B$156=$A34)"),200.0) -> 200 | I34: =IFERROR(__xludf.DUMMYFUNCTION("FILTER('Sources - Averages (Berlin)'!$G$5:$G$156,'Sources - Averages (Berlin)'!$A$5:$A$156=I$4,'Sources - Averages (Berlin)'!$B$5:$B$156=$A34)"),500.0) -> 500 | J34: =IFERROR(__xludf.DUMMYFUNCTION("FILTER('Sources - Averages (Berlin)'!$G$5:$G$156,'Sources - Averages (Berlin)'!$A$5:$A$156=J$4,'Sources - Averages (Berlin)'!$B$5:$B$156=$A34)"),100.0) -> 100 | K34: =IFERROR(__xludf.DUMMYFUNCTION("FILTER('Sources - Averages (Berlin)'!$G$5:$G$156,'Sources - Averages (Berlin)'!$A$5:$A$156=K$4,'Sources - Averages (Berlin)'!$B$5:$B$156=$A34)"),45000.0) -> 45000 | M34: =IFERROR(__xludf.DUMMYFUNCTION("FILTER('Sources - Averages (Berlin)'!$G$5:$G$156,'Sources - Averages (Berlin)'!$A$5:$A$156=M$4,'Sources - Averages (Berlin)'!$B$5:$B$156=$A34)"),4375.0) -> 4375 | N34: {=SUM(B34:M34)} -> 73175 | O34: =N34-B34 -> 60175
A36: Average attendance per event (years with data):
A37: DGB Berlin (main trade-union rally) | B37: {=IFERROR(AVERAGE(B5:B34),"-")} -> 13997.5 | C37: {=COUNT(B5:B34)} -> 30 | D37: years with data
A38: PDS/Ost (1990-1994) | B38: {=IFERROR(AVERAGE(C5:C34),"-")} -> 7125 | C38: {=COUNT(C5:C34)} -> 4 | D38: years with data
A39: Revolutionary May 1st (joint march, 1990-1995) | B39: {=IFERROR(AVERAGE(D5:D34),"-")} -> 8011.1111 | C39: {=COUNT(D5:D34)} -> 6 | D39: years with data
A40: Revolutionary May 1st (18:00) | B40: {=IFERROR(AVERAGE(E5:E34),"-")} -> 10736.111 | C40: {=COUNT(E5:E34)} -> 24 | D40: years with data
A41: Revolutionary May 1st (13:00) | B41: {=IFERROR(AVERAGE(F5:F34),"-")} -> 1606.1404 | C41: {=COUNT(F5:F34)} -> 19 | D41: years with data
A42: PDS/Ost (1995-2002) | B42: {=IFERROR(AVERAGE(G5:G34),"-")} -> 5100 | C42: {=COUNT(G5:G34)} -> 8 | D42: years with data
...

Sheet Event Types - Warsaw
A1: Event types per year - Warsaw, 1990-2019
A2: Counts by event type each year, plus descriptive statistics of how the mix changed over time (source: pipeline/output/pole_*.csv, plus flagged additions - see note)
A4: Year | B4: Total events | C4: Demonstrations | D4: Festivals | E4: Commemorations | F4: Rallies | G4: Counter-demonstrations | H4: Meetings | I4: Happenings | J4: Corsos (car parades) | K4: Mass (Solidarity) | L4: Main rally/festival location
A5: 1990 | B5: =SUM(C5:K5) -> 15 | C5: 5 | D5: 1 | E5: 4 | G5: 1 | H5: 3 | K5: 1 | L5: plac Teatralny
A6: 1991 | B6: =SUM(C6:K6) -> 10 | C6: 5 | E6: 3 | G6: 1 | K6: 1 | L6: plac Teatralny
A7: 1992 | B7: =SUM(C7:K7) -> 8 | C7: 3 | E7: 3 | G7: 1 | K7: 1 | L7: plac Teatralny
A8: 1993 | B8: =SUM(C8:K8) -> 10 | C8: 3 | D8: 1 | E8: 4 | G8: 1 | K8: 1 | L8: plac Teatralny
A9: 1994 | B9: =SUM(C9:K9) -> 12 | C9: 4 | D9: 1 | E9: 4 | G9: 1 | I9: 1 | K9: 1 | L9: plac Teatralny
A10: 1995 | B10: =SUM(C10:K10) -> 13 | C10: 4 | D10: 1 | E10: 4 | G10: 3 | K10: 1 | L10: plac Teatralny
A11: 1996 | B11: =SUM(C11:K11) -> 12 | C11: 5 | D11: 1 | E11: 4 | G11: 1 | K11: 1 | L11: plac Grzybowski
A12: 1997 | B12: =SUM(C12:K12) -> 13 | C12: 2 | D12: 2 | E12: 6 | G12: 3 | L12: plac Grzybowski
A13: 1998 | B13: =SUM(C13:K13) -> 11 | C13: 3 | D13: 1 | E13: 4 | G13: 1 | I13: 1 | K13: 1 | L13: plac Grzybowski
A14: 1999 | B14: =SUM(C14:K14) -> 10 | C14: 2 | D14: 1 | E14: 4 | G14: 2 | K14: 1 | L14: plac Grzybowski
A15: 2000 | B15: =SUM(C15:K15) -> 11 | C15: 3 | D15: 1 | E15: 4 | G15: 1 | I15: 1 | K15: 1 | L15: plac Grzybowski
A16: 2001 | B16: =SUM(C16:K16) -> 10 | C16: 4 | D16: 1 | E16: 3 | G16: 1 | K16: 1 | L16: plac Grzybowski
A17: 2002 | B17: =SUM(C17:K17) -> 9 | C17: 3 | D17: 1 | E17: 2 | G17: 2 | K17: 1 | L17: Sejm RP
A18: 2003 | B18: =SUM(C18:K18) -> 10 | C18: 5 | D18: 1 | E18: 2 | G18: 1 | K18: 1 | L18: Sejm RP
A19: 2004 | B19: =SUM(C19:K19) -> 7 | C19: 3 | D19: 1 | E19: 2 | K19: 1 | L19: Sejm RP
A20: 2005 | B20: =SUM(C20:K20) -> 8 | C20: 2 | D20: 2 | E20: 3 | K20: 1 | L20: Sejm RP
A21: 2006 | B21: =SUM(C21:K21) -> 6 | C21: 2 | E21: 3 | K21: 1 | L21: Sejm RP
A22: 2007 | B22: =SUM(C22:K22) -> 11 | C22: 4 | D22: 1 | E22: 3 | G22: 1 | I22: 1 | K22: 1 | L22: Sejm RP
A23: 2008 | B23: =SUM(C23:K23) -> 9 | C23: 4 | D23: 1 | E23: 3 | K23: 1 | L23: Sejm RP
A24: 2009 | B24: =SUM(C24:K24) -> 10 | C24: 4 | E24: 3 | G24: 2 | K24: 1 | L24: Sejm RP
A25: 2010 | B25: =SUM(C25:K25) -> 4 | C25: 2 | E25: 2 | L25: Sejm RP
A26: 2011 | B26: =SUM(C26:K26) -> 7 | C26: 3 | E26: 4 | L26: Wiec pod OPZZ
A27: 2012 | B27: =SUM(C27:K27) -> 7 | C27: 4 | E27: 2 | H27: 1 | L27: Park Rydza-Śmigłego
A28: 2013 | B28: =SUM(C28:K28) -> 7 | C28: 3 | D28: 1 | E28: 3 | L28: Park Rydza-Śmigłego
A29: 2014 | B29: =SUM(C29:K29) -> 9 | C29: 3 | D29: 1 | E29: 3 | I29: 2 | L29: Park Rydza-Śmigłego
A30: 2015 | B30: =SUM(C30:K30) -> 6 | C30: 3 | D30: 1 | E30: 2
A31: 2016 | B31: =SUM(C31:K31) -> 6 | C31: 3 | D31: 1 | E31: 2 | L31: Sejm RP
A32: 2017 | B32: =SUM(C32:K32) -> 7 | C32: 2 | D32: 2 | E32: 3 | L32: Krakowskie Przedmieście
A33: 2018 | B33: =SUM(C33:K33) -> 9 | C33: 4 | D33: 2 | E33: 2 | G33: 1 | L33: Krakowskie Przedmieście
A34: 2019 | B34: =SUM(C34:K34) -> 13 | C34: 3 | D34: 4 | E34: 6
A36: Totals, 1990-2019
A37: Event type | B37: Total count | C37: Avg. per year | D37: Years present | E37: Share of all events
A38: Demonstrations | B38: =SUM(C5:C34) -> 100 | C38: =IFERROR(AVERAGE(C5:C34),0) -> 3.3333333 | D38: =COUNT(C5:C34) -> 30 | E38: =IFERROR((B38/$B$46),"") -> 0.35714286
A39: Festivals | B39: =SUM(D5:D34) -> 30 | C39: =IFERROR(AVERAGE(D5:D34),0) -> 1.3043478 | D39: =COUNT(D5:D34) -> 23 | E39: =IFERROR((B39/$B$46),"") -> 0.10714286
A40: Commemorations | B40: =SUM(E5:E34) -> 97 | C40: =IFERROR(AVERAGE(E5:E34),0) -> 3.2333333 | D40: =COUNT(E5:E34) -> 30 | E40: =IFERROR((B40/$B$46),"") -> 0.34642857
A41: Counter-demonstrations | B41: =SUM(G5:G34) -> 24 | C41: =IFERROR(AVERAGE(G5:G34),0) -> 1.4117647 | D41: =COUNT(G5:G34) -> 17 | E41: =IFERROR((B41/$B$46),"") -> 0.085714286
A42: Meetings | B42: =SUM(H5:H34) -> 4 | C42: =IFERROR(AVERAGE(H5:H34),0) -> 2 | D42: =COUNT(H5:H34) -> 2 | E42: =IFERROR((B42/$B$46),"") -> 0.014285714
...

Sheet Event Types - Berlin
A1: Event types per year - Berlin, 1990-2019
A2: Counts by event type each year, plus descriptive statistics of how the mix changed over time
A4: Year | B4: Total events | C4: Demonstrations | D4: Festivals* | E4: Commemorations | F4: Rallies | G4: Counter-demonstrations | H4: Meetings | I4: Happenings | J4: Corsos (car parades) | K4: Main rally/festival location
A5: 1990 | B5: =SUM(C5:J5) -> 13 | C5: 9 | D5: 4 | K5: Platz der Republik
A6: 1991 | B6: =SUM(C6:J6) -> 18 | C6: 7 | D6: 10 | H6: 1 | K6: Platz der Republik
A7: 1992 | B7: =SUM(C7:J7) -> 24 | C7: 10 | D7: 14 | K7: Lustgarten
A8: 1993 | B8: =SUM(C8:J8) -> 20 | C8: 10 | D8: 8 | G8: 1 | H8: 1 | K8: Lustgarten
A9: 1994 | B9: =SUM(C9:J9) -> 26 | C9: 13 | D9: 12 | G9: 1 | K9: Lustgarten
A10: 1995 | B10: =SUM(C10:J10) -> 19 | C10: 6 | D10: 12 | J10: 1 | K10: Köllnischer Park
A11: 1996 | B11: =SUM(C11:J11) -> 19 | C11: 13 | D11: 6 | K11: Rotes Rathaus
A12: 1997 | B12: =SUM(C12:J12) -> 18 | C12: 8 | D12: 10 | K12: Rotes Rathaus
A13: 1998 | B13: =SUM(C13:J13) -> 13 | C13: 10 | D13: 3 | K13: Rotes Rathaus
A14: 1999 | B14: =SUM(C14:J14) -> 14 | C14: 11 | D14: 3 | K14: Rotes Rathaus
A15: 2000 | B15: =SUM(C15:J15) -> 23 | C15: 10 | D15: 12 | J15: 1 | K15: Rotes Rathaus
A16: 2001 | B16: =SUM(C16:J16) -> 19 | C16: 14 | D16: 5 | K16: Rotes Rathaus
A17: 2002 | B17: =SUM(C17:J17) -> 24 | C17: 7 | D17: 13 | G17: 3 | I17: 1 | K17: Rotes Rathaus
A18: 2003 | B18: =SUM(C18:J18) -> 13 | C18: 5 | D18: 5 | G18: 2 | J18: 1 | K18: Rotes Rathaus
A19: 2004 | B19: =SUM(C19:J19) -> 12 | C19: 8 | D19: 3 | G19: 1 | K19: Rotes Rathaus
A20: 2005 | B20: =SUM(C20:J20) -> 19 | C20: 9 | D20: 8 | J20: 2 | K20: Rotes Rathaus
A21: 2006 | B21: =SUM(C21:J21) -> 15 | C21: 7 | D21: 4 | J21: 4 | K21: Brandenburger Tor
A22: 2007 | B22: =SUM(C22:J22) -> 16 | C22: 6 | D22: 6 | J22: 4 | K22: Brandenburger Tor
A23: 2008 | B23: =SUM(C23:J23) -> 11 | C23: 5 | D23: 4 | J23: 2 | K23: Brandenburger Tor
A24: 2009 | B24: =SUM(C24:J24) -> 15 | C24: 5 | D24: 6 | G24: 1 | J24: 3 | K24: Brandenburger Tor
A25: 2010 | B25: =SUM(C25:J25) -> 19 | C25: 8 | D25: 7 | G25: 2 | J25: 2 | K25: Brandenburger Tor
A26: 2011 | B26: =SUM(C26:J26) -> 14 | C26: 5 | D26: 6 | J26: 3 | K26: Brandenburger Tor
A27: 2012 | B27: =SUM(C27:J27) -> 15 | C27: 4 | D27: 8 | G27: 1 | J27: 2 | K27: Brandenburger Tor
A28: 2013 | B28: =SUM(C28:J28) -> 14 | C28: 6 | D28: 5 | G28: 1 | J28: 2 | K28: Brandenburger Tor
A29: 2014 | B29: =SUM(C29:J29) -> 11 | C29: 4 | D29: 5 | J29: 2 | K29: Brandenburger Tor
A30: 2015 | B30: =SUM(C30:J30) -> 17 | C30: 7 | D30: 7 | G30: 1 | J30: 2 | K30: Brandenburger Tor
A31: 2016 | B31: =SUM(C31:J31) -> 25 | C31: 8 | D31: 10 | G31: 5 | J31: 2 | K31: Brandenburger Tor
A32: 2017 | B32: =SUM(C32:J32) -> 21 | C32: 7 | D32: 11 | G32: 1 | J32: 2 | K32: Brandenburger Tor
A33: 2018 | B33: =SUM(C33:J33) -> 15 | C33: 4 | D33: 9 | J33: 2 | K33: Brandenburger Tor
A34: 2019 | B34: =SUM(C34:J34) -> 18 | C34: 7 | D34: 8 | E34: 1 | J34: 2 | K34: Brandenburger Tor
A35: *Does not include district level festivals
A36: Totals, 1990-2019
A37: Event type | B37: Total count | C37: Avg. per year | D37: Years present | E37: Share of all events
A38: Demonstrations | B38: =SUM(C5:C34) -> 233 | C38: =IFERROR(AVERAGE(C5:C34),0) -> 7.7666667 | D38: =COUNT(C5:C34) -> 30 | E38: =IFERROR((B38/$B$44),"") -> 0.44980695
A39: Festivals | B39: =SUM(D5:D34) -> 224 | C39: =IFERROR(AVERAGE(D5:D34),0) -> 7.4666667 | D39: =COUNT(D5:D34) -> 30 | E39: =IFERROR((B39/$B$44),"") -> 0.43243243
A40: Commemorations | B40: =SUM(E5:E34) -> 1 | C40: =IFERROR(AVERAGE(E5:E34),0) -> 1 | D40: =COUNT(E5:E34) -> 1 | E40: =IFERROR((B40/$B$44),"") -> 0.0019305019
A41: Counter-demonstrations | B41: =SUM(G5:G34) -> 20 | C41: =IFERROR(AVERAGE(G5:G34),0) -> 1.6666667 | D41: =COUNT(G5:G34) -> 12 | E41: =IFERROR((B41/$B$44),"") -> 0.038610039
...

Sheet Sources - Observations (Berlin)
A1: Source observations - attendance, Berlin
A2: Individual cited estimates (press / organisers / police) behind the yearly averages in the Attendance/Events sheets
A4: Event | B4: Year | C4: Attendance | D4: Source category | E4: Source / citation
A5: Anti-Nazi counter-demonstration | B5: 1992 | C5: 200 | D5: press | E5: Gluckspilz
A6: Anti-Nazi counter-demonstration | B6: 1994 | C6: 400 | D6: press | E6: taz
A7: Anti-Nazi counter-demonstration | B7: 1994 | C7: 500 | D7: press | E7: Gluckspilz
A8: Anti-Nazi counter-demonstration | B8: 1996 | C8: 40 | D8: organisers | E8: Breitenbach (JW 3.05)
A9: Anti-Nazi counter-demonstration | B9: 2000 | C9: 10000 | D9: press | E9: ND
