Workbook

Sheet ToC
A2: Dane

Sheet Dane
A1: Rok | B1: Liczba uczestników | C1: Źródło | D1: Kategoria
A2: 1990 | B2: 60000 | C2: Junge Welt | D2: prasa
A3: 1990 | B3: 60000 | C3: Neues Deutschland | D3: prasa
A4: 1990 | B4: 50000 | C4: TAZ | D4: prasa
A5: 1990 | B5: - | C5: - | D5: organizatorzy
A6: 1990 | B6: - | C6: - | D6: organizatorzy
A7: 1991 | B7: 10000 | C7: rbb | D7: prasa
A8: 1991 | B8: 5000 | C8: "mehrere Tausend" (taz) | D8: prasa
A9: 1991 | B9: 15000 | C9: Christine Bretz, DGB Berlin (taz) | D9: organizatorzy
A10: 1992 | B10: 8000 | C10: Kronika Berlina | D10: policja
A11: 1992 | B11: 15000 | C11: Berliner Morgenpost DGBG657 | D11: prasa
A12: 1992 | B12: 40000 | C12: Neues Deutschland (Kritische Gewerkschaften s.71) | D12: prasa
A13: 1992 | B13: 25000 | C13: DGBG000656 | D13: organizatorzy
A14: 1992 | B14: 10000 | C14: rbb | D14: prasa
A15: 1992 | B15: 40000 | C15: Berliner Zeitung 2.05.1992 | D15: prasa
A16: 1993 | B16: 15000 | C16: Taz 3.05 | D16: prasa
A17: 1993 | B17: 30000 | C17: Neues Deutschland 3.05; Berliner Zeitung 3.05 za DGB | D17: organizatorzy
A18: 1993 | B18: 5000 | C18: rbb | D18: prasa
... A96: 2014 | B96: 10000 | C96: Neues Deutschland | D96: prasa
A97: 2015
A98: 2015 | B98: 15000 | C98: rbb za DGB | D98: organizatorzy
A99: 2015
A100: 2016 | B100: 14000 | C100: TAZ liveticker 1.05 za organizatorami | D100: organizatorzy
A101: 2017 | B101: 14000 | C101: BZ / DGB BB internet (za organizatorami) | D101: organizatorzy
A102: 2018 | B102: 14000 | C102: Neues Deutschland (za organizatorami) | D102: organizatorzy
A103: 2018 | B103: 5000 | C103: Policja | D103: policja
A104: 2019 | B104: 13000 | C104: DGB online | D104: organizatorzy
A105: 2020 | B105: 0 | C105: odwołano
A106: 2021 | B106: 300 | C106: Tylko na zaproszenie | D106: organizatorzy
A107: 2022 | B107: 7500 | C107: BM | D107: prasa
A108: 2022 | B108: 9500 | C108: polizei Meldung | D108: policja
A109: 2023 | B109: 6000 | C109: polizei Meldung | D109: policja
A110: 2024 | B110: 14000 | C110: polizei Meldung | D110: policja
A111: 2024 | B111: 7500 | C111: BZ | D111: prasa
A112: 2024 | B112: 12500 | C112: Naturfreunde | D112: prasa
A113: 2025 | B113: 6600 | C113: polizei Meldung | D113: policja
A114: 2025 | B114: 11000 | C114: rbb | D114: prasa
A115: 2026 | B115: 7100 | C115: polizei Meldung | D115: policja
A116: 2026 | B116: 12000 | C116: Naturfreunde | D116: organizatorzy

Sheet Średnie i wykres
A1: Rok | B1: Prasa | C1: Organizatorzy | D1: Policja | E1: Średnia ogólna | F1: średnia metoda alt | G1: Różnica % | H1: średnia ruchoma
A2: 1990 | B2: =IFERROR(AVERAGEIFS(Dane!$B$2:$B$116,Dane!$A$2:$A$116,$A2,Dane!$D$2:$D$116,"prasa"),"") -> 56666.667 | C2: =IFERROR(AVERAGEIFS(Dane!$B$2:$B$116,Dane!$A$2:$A$116,$A2,Dane!$D$2:$D$116,"organizatorzy"),"") | D2: =IFERROR(AVERAGEIFS(Dane!$B$2:$B$116,Dane!$A$2:$A$116,$A2,Dane!$D$2:$D$116,"policja"),"") | E2: =IFERROR((0.5*IF(B2<>"",B2,0) + 0.25*IF(C2<>"",C2,0) + 0.25*IF(D2<>"",D2,0))/(0.5*IF(B2<>"",1,0) + 0.25*IF(C2<>"",1,0) + 0.25*IF(D2<>"",1,0)),"") -> 56666.667 | F2: =IFERROR(AVERAGEIFS(Dane!$B$2:$B$116,Dane!$A$2:$A$116,$A2),"") -> 56666.667 | G2: =E2-F2 -> 0
A3: 1991 | B3: =IFERROR(AVERAGEIFS(Dane!$B$2:$B$116,Dane!$A$2:$A$116,$A3,Dane!$D$2:$D$116,"prasa"),"") -> 7500 | C3: =IFERROR(AVERAGEIFS(Dane!$B$2:$B$116,Dane!$A$2:$A$116,$A3,Dane!$D$2:$D$116,"organizatorzy"),"") -> 15000 | D3: =IFERROR(AVERAGEIFS(Dane!$B$2:$B$116,Dane!$A$2:$A$116,$A3,Dane!$D$2:$D$116,"policja"),"") | E3: =IFERROR((0.5*IF(B3<>"",B3,0) + 0.25*IF(C3<>"",C3,0) + 0.25*IF(D3<>"",D3,0))/(0.5*IF(B3<>"",1,0) + 0.25*IF(C3<>"",1,0) + 0.25*IF(D3<>"",1,0)),"") -> 10000 | F3: =IFERROR(AVERAGEIFS(Dane!$B$2:$B$116,Dane!$A$2:$A$116,$A3),"") -> 10000 | G3: =E3-F3 -> 0 | H3: =AVERAGE(F2:F4) -> 29888.889
A4: 1992 | B4: =IFERROR(AVERAGEIFS(Dane!$B$2:$B$116,Dane!$A$2:$A$116,$A4,Dane!$D$2:$D$116,"prasa"),"") -> 26250 | C4: =IFERROR(AVERAGEIFS(Dane!$B$2:$B$116,Dane!$A$2:$A$116,$A4,Dane!$D$2:$D$116,"organizatorzy"),"") -> 25000 | D4: =IFERROR(AVERAGEIFS(Dane!$B$2:$B$116,Dane!$A$2:$A$116,$A4,Dane!$D$2:$D$116,"policja"),"") -> 8000 | E4: =IFERROR((0.5*IF(B4<>"",B4,0) + 0.25*IF(C4<>"",C4,0) + 0.25*IF(D4<>"",D4,0))/(0.5*IF(B4<>"",1,0) + 0.25*IF(C4<>"",1,0) + 0.25*IF(D4<>"",1,0)),"") -> 21375 | F4: =IFERROR(AVERAGEIFS(Dane!$B$2:$B$116,Dane!$A$2:$A$116,$A4),"") -> 23000 | G4: =E4-F4 -> -1625 | H4: =AVERAGE(F3:F5) -> 16555.556
A5: 1993 | B5: =IFERROR(AVERAGEIFS(Dane!$B$2:$B$116,Dane!$A$2:$A$116,$A5,Dane!$D$2:$D$116,"prasa"),"") -> 10000 | C5: =IFERROR(AVERAGEIFS(Dane!$B$2:$B$116,Dane!$A$2:$A$116,$A5,Dane!$D$2:$D$116,"organizatorzy"),"") -> 30000 | D5: =IFERROR(AVERAGEIFS(Dane!$B$2:$B$116,Dane!$A$2:$A$116,$A5,Dane!$D$2:$D$116,"policja"),"") | E5: =IFERROR((0.5*IF(B5<>"",B5,0) + 0.25*IF(C5<>"",C5,0) + 0.25*IF(D5<>"",D5,0))/(0.5*IF(B5<>"",1,0) + 0.25*IF(C5<>"",1,0) + 0.25*IF(D5<>"",1,0)),"") -> 16666.667 | F5: =IFERROR(AVERAGEIFS(Dane!$B$2:$B$116,Dane!$A$2:$A$116,$A5),"") -> 16666.667 | G5: =E5-F5 -> 0 | H5: =AVERAGE(F4:F6) -> 15222.222
A6: 1994 | B6: =IFERROR(AVERAGEIFS(Dane!$B$2:$B$116,Dane!$A$2:$A$116,$A6,Dane!$D$2:$D$116,"prasa"),"") -> 5000 | C6: =IFERROR(AVERAGEIFS(Dane!$B$2:$B$116,Dane!$A$2:$A$116,$A6,Dane!$D$2:$D$116,"organizatorzy"),"") -> 8000 | D6: =IFERROR(AVERAGEIFS(Dane!$B$2:$B$116,Dane!$A$2:$A$116,$A6,Dane!$D$2:$D$116,"policja"),"") | E6: =IFERROR((0.5*IF(B6<>"",B6,0) + 0.25*IF(C6<>"",C6,0) + 0.25*IF(D6<>"",D6,0))/(0.5*IF(B6<>"",1,0) + 0.25*IF(C6<>"",1,0) + 0.25*IF(D6<>"",1,0)),"") -> 6000 | F6: =IFERROR(AVERAGEIFS(Dane!$B$2:$B$116,Dane!$A$2:$A$116,$A6),"") -> 6000 | G6: =E6-F6 -> 0 | H6: =AVERAGE(F5:F7) -> 10022.222
A7: 1995 | B7: =IFERROR(AVERAGEIFS(Dane!$B$2:$B$116,Dane!$A$2:$A$116,$A7,Dane!$D$2:$D$116,"prasa"),"") -> 6750 | C7: =IFERROR(AVERAGEIFS(Dane!$B$2:$B$116,Dane!$A$2:$A$116,$A7,Dane!$D$2:$D$116,"organizatorzy"),"") -> 10000 | D7: =IFERROR(AVERAGEIFS(Dane!$B$2:$B$116,Dane!$A$2:$A$116,$A7,Dane!$D$2:$D$116,"policja"),"") | E7: =IFERROR((0.5*IF(B7<>"",B7,0) + 0.25*IF(C7<>"",C7,0) + 0.25*IF(D7<>"",D7,0))/(0.5*IF(B7<>"",1,0) + 0.25*IF(C7<>"",1,0) + 0.25*IF(D7<>"",1,0)),"") -> 7833.3333 | F7: =IFERROR(AVERAGEIFS(Dane!$B$2:$B$116,Dane!$A$2:$A$116,$A7),"") -> 7400 | G7: =E7-F7 -> 433.33333 | H7: =AVERAGE(F6:F8) -> 10022.222
A8: 1996 | B8: =IFERROR(AVERAGEIFS(Dane!$B$2:$B$116,Dane!$A$2:$A$116,$A8,Dane!$D$2:$D$116,"prasa"),"") -> 16666.667 | C8: =IFERROR(AVERAGEIFS(Dane!$B$2:$B$116,Dane!$A$2:$A$116,$A8,Dane!$D$2:$D$116,"organizatorzy"),"") | D8: =IFERROR(AVERAGEIFS(Dane!$B$2:$B$116,Dane!$A$2:$A$116,$A8,Dane!$D$2:$D$116,"policja"),"") | E8: =IFERROR((0.5*IF(B8<>"",B8,0) + 0.25*IF(C8<>"",C8,0) + 0.25*IF(D8<>"",D8,0))/(0.5*IF(B8<>"",1,0) + 0.25*IF(C8<>"",1,0) + 0.25*IF(D8<>"",1,0)),"") -> 16666.667 | F8: =IFERROR(AVERAGEIFS(Dane!$B$2:$B$116,Dane!$A$2:$A$116,$A8),"") -> 16666.667 | G8: =E8-F8 -> 0 | H8: =AVERAGE(F7:F9) -> 11188.889
A9: 1997 | B9: =IFERROR(AVERAGEIFS(Dane!$B$2:$B$116,Dane!$A$2:$A$116,$A9,Dane!$D$2:$D$116,"prasa"),"") -> 5833.3333 | C9: =IFERROR(AVERAGEIFS(Dane!$B$2:$B$116,Dane!$A$2:$A$116,$A9,Dane!$D$2:$D$116,"organizatorzy"),"") -> 25000 | D9: =IFERROR(AVERAGEIFS(Dane!$B$2:$B$116,Dane!$A$2:$A$116,$A9,Dane!$D$2:$D$116,"policja"),"") -> 5000 | E9: =IFERROR((0.5*IF(B9<>"",B9,0) + 0.25*IF(C9<>"",C9,0) + 0.25*IF(D9<>"",D9,0))/(0.5*IF(B9<>"",1,0) + 0.25*IF(C9<>"",1,0) + 0.25*IF(D9<>"",1,0)),"") -> 10416.667 | F9: =IFERROR(AVERAGEIFS(Dane!$B$2:$B$116,Dane!$A$2:$A$116,$A9),"") -> 9500 | G9: =E9-F9 -> 916.66667 | H9: =AVERAGE(F8:F10) -> 13347.222
A10: 1998 | B10: =IFERROR(AVERAGEIFS(Dane!$B$2:$B$116,Dane!$A$2:$A$116,$A10,Dane!$D$2:$D$116,"prasa"),"") -> 12666.667 | C10: =IFERROR(AVERAGEIFS(Dane!$B$2:$B$116,Dane!$A$2:$A$116,$A10,Dane!$D$2:$D$116,"organizatorzy"),"") -> 17500 | D10: =IFERROR(AVERAGEIFS(Dane!$B$2:$B$116,Dane!$A$2:$A$116,$A10,Dane!$D$2:$D$116,"policja"),"") | E10: =IFERROR((0.5*IF(B10<>"",B10,0) + 0.25*IF(C10<>"",C10,0) + 0.25*IF(D10<>"",D10,0))/(0.5*IF(B10<>"",1,0) + 0.25*IF(C10<>"",1,0) + 0.25*IF(D10<>"",1,0)),"") -> 14277.778 | F10: =IFERROR(AVERAGEIFS(Dane!$B$2:$B$116,Dane!$A$2:$A$116,$A10),"") -> 13875 | G10: =E10-F10 -> 402.77778 | H10: =AVERAGE(F9:F11) -> 11258.333
A11: 1999 | B11: =IFERROR(AVERAGEIFS(Dane!$B$2:$B$116,Dane!$A$2:$A$116,$A11,Dane!$D$2:$D$116,"prasa"),"") -> 10000 | C11: =IFERROR(AVERAGEIFS(Dane!$B$2:$B$116,Dane!$A$2:$A$116,$A11,Dane!$D$2:$D$116,"organizatorzy"),"") -> 15000 | D11: =IFERROR(AVERAGEIFS(Dane!$B$2:$B$116,Dane!$A$2:$A$116,$A11,Dane!$D$2:$D$116,"policja"),"") -> 7000 | E11: =IFERROR((0.5*IF(B11<>"",B11,0) + 0.25*IF(C11<>"",C11,0) + 0.25*IF(D11<>"",D11,0))/(0.5*IF(B11<>"",1,0) + 0.25*IF(C11<>"",1,0) + 0.25*IF(D11<>"",1,0)),"") -> 10500 | F11: =IFERROR(AVERAGEIFS(Dane!$B$2:$B$116,Dane!$A$2:$A$116,$A11),"") -> 10400 | G11: =E11-F11 -> 100 | H11: =AVERAGE(F10:F12) -> 11813.889
A12: 2000 | B12: =IFERROR(AVERAGEIFS(Dane!$B$2:$B$116,Dane!$A$2:$A$116,$A12,Dane!$D$2:$D$116,"prasa"),"") -> 10000 | C12: =IFERROR(AVERAGEIFS(Dane!$B$2:$B$116,Dane!$A$2:$A$116,$A12,Dane!$D$2:$D$116,"organizatorzy"),"") -> 15000 | D12: =IFERROR(AVERAGEIFS(Dane!$B$2:$B$116,Dane!$A$2:$A$116,$A12,Dane!$D$2:$D$116,"policja"),"") -> 7000 | E12: =IFERROR((0.5*IF(B12<>"",B12,0) + 0.25*IF(C12<>"",C12,0) + 0.25*IF(D12<>"",D12,0))/(0.5*IF(B12<>"",1,0) + 0.25*IF(C12<>"",1,0) + 0.25*IF(D12<>"",1,0)),"") -> 10500 | F12: =IFERROR(AVERAGEIFS(Dane!$B$2:$B$116,Dane!$A$2:$A$116,$A12),"") -> 11166.667 | G12: =E12-F12 -> -666.66667 | H12: =AVERAGE(F11:F13) -> 12800
A13: 2001 | B13: =IFERROR(AVERAGEIFS(Dane!$B$2:$B$116,Dane!$A$2:$A$116,$A13,Dane!$D$2:$D$116,"prasa"),"") -> 16833.333 | C13: =IFERROR(AVERAGEIFS(Dane!$B$2:$B$116,Dane!$A$2:$A$116,$A13,Dane!$D$2:$D$116,"organizatorzy"),"") | D13: =IFERROR(AVERAGEIFS(Dane!$B$2:$B$116,Dane!$A$2:$A$116,$A13,Dane!$D$2:$D$116,"policja"),"") | E13: =IFERROR((0.5*IF(B13<>"",B13,0) + 0.25*IF(C13<>"",C13,0) + 0.25*IF(D13<>"",D13,0))/(0.5*IF(B13<>"",1,0) + 0.25*IF(C13<>"",1,0) + 0.25*IF(D13<>"",1,0)),"") -> 16833.333 | F13: =IFERROR(AVERAGEIFS(Dane!$B$2:$B$116,Dane!$A$2:$A$116,$A13),"") -> 16833.333 | G13: =E13-F13 -> 0 | H13: =AVERAGE(F12:F14) -> 13833.333
A14: 2002 | B14: =IFERROR(AVERAGEIFS(Dane!$B$2:$B$116,Dane!$A$2:$A$116,$A14,Dane!$D$2:$D$116,"prasa"),"") -> 11000 | C14: =IFERROR(AVERAGEIFS(Dane!$B$2:$B$116,Dane!$A$2:$A$116,$A14,Dane!$D$2:$D$116,"organizatorzy"),"") -> 25000 | D14: =IFERROR(AVERAGEIFS(Dane!$B$2:$B$116,Dane!$A$2:$A$116,$A14,Dane!$D$2:$D$116,"policja"),"") -> 7000 | E14: =IFERROR((0.5*IF(B14<>"",B14,0) + 0.25*IF(C14<>"",C14,0) + 0.25*IF(D14<>"",D14,0))/(0.5*IF(B14<>"",1,0) + 0.25*IF(C14<>"",1,0) + 0.25*IF(D14<>"",1,0)),"") -> 13500 | F14: =IFERROR(AVERAGEIFS(Dane!$B$2:$B$116,Dane!$A$2:$A$116,$A14),"") -> 13500 | G14: =E14-F14 -> 0 | H14: =AVERAGE(F13:F15) -> 14611.111
... A37: 2025 | B37: =IFERROR(AVERAGEIFS(Dane!$B$2:$B$116,Dane!$A$2:$A$116,$A37,Dane!$D$2:$D$116,"prasa"),"") -> 11000 | C37: =IFERROR(AVERAGEIFS(Dane!$B$2:$B$116,Dane!$A$2:$A$116,$A37,Dane!$D$2:$D$116,"organizatorzy"),"") | D37: =IFERROR(AVERAGEIFS(Dane!$B$2:$B$116,Dane!$A$2:$A$116,$A37,Dane!$D$2:$D$116,"policja"),"") -> 6600 | E37: =IFERROR((0.5*IF(B37<>"",B37,0) + 0.25*IF(C37<>"",C37,0) + 0.25*IF(D37<>"",D37,0))/(0.5*IF(B37<>"",1,0) + 0.25*IF(C37<>"",1,0) + 0.25*IF(D37<>"",1,0)),"") -> 9533.3333 | F37: =IFERROR(AVERAGEIFS(Dane!$B$2:$B$116,Dane!$A$2:$A$116,$A37),"") -> 8800 | G37: =E37-F37 -> 733.33333 | H37: =AVERAGE(F36:F38) -> 9894.4444
A38: 2026 | B38: =IFERROR(AVERAGEIFS(Dane!$B$2:$B$116,Dane!$A$2:$A$116,$A38,Dane!$D$2:$D$116,"prasa"),"") | C38: =IFERROR(AVERAGEIFS(Dane!$B$2:$B$116,Dane!$A$2:$A$116,$A38,Dane!$D$2:$D$116,"organizatorzy"),"") -> 12000 | D38: =IFERROR(AVERAGEIFS(Dane!$B$2:$B$116,Dane!$A$2:$A$116,$A38,Dane!$D$2:$D$116,"policja"),"") -> 7100 | E38: =IFERROR((0.5*IF(B38<>"",B38,0) + 0.25*IF(C38<>"",C38,0) + 0.25*IF(D38<>"",D38,0))/(0.5*IF(B38<>"",1,0) + 0.25*IF(C38<>"",1,0) + 0.25*IF(D38<>"",1,0)),"") -> 9550 | F38: =IFERROR(AVERAGEIFS(Dane!$B$2:$B$116,Dane!$A$2:$A$116,$A38),"") -> 9550 | G38: =E38-F38 -> 0
D40: =IFERROR(__xludf.DUMMYFUNCTION("ARRAYFORMULA(JOIN("", "", IF(F2:F31="""", ""null"", ROUND(F2:F31, 0))))"),"56667, 10000, 23000, 16667, 6000, 7400, 16667, 9500, 13875, 10400, 11167, 16833, 13500, 13500, 18500, 10500, 13500, 10500, 9125, 13500, 9750, 11500, 12625, 9750, 10000, 15000, 14000, 14000, 9500, 13000") -> 56667, 10000, 23000, 16667, 6000, 7400, 16667, 9500, 13875, 10400, 11167, 16833, 13500, 13500, 18500, 10500, 13500, 10500, 9125, 13500, 9750, 11500, 12625, 9750, 10000, 15000, 14000, 14000, 9500, 13000
C46: andere Gruppen
C47: Datum | D47: Titel | E47: Thema | F47: Dauer | G47: Archiv ID | H47: FIDOS
C48: 32994 | D48: 100 Jahre 1. Mai | E48: 100 Jahre 1. Mai | F48: 75'28" | G48: 216532 | H48: 73462
C49: 33725 | D49: Tag der Arbeit | E49: Sternmarsch des DGB in Berlin | F49: 28'47" | G49: 218577 | H49: 77480
C50: 34090 | D50: Abendschau | E50: 1.Mai 1993 - offizielle Demonstrationen in Berlin | F50: 2'36" | G50: 120363 | H50: 80233
C51: 34820 | D51: Abendschau | E51: 1.Mai 1995 - DGB-Kundgebung | F51: 1'28" | G51: 122296 | H51: 86482
C52: 35187 | D52: SpätAbendschau | E52: Bilanz 1.Mai 1996 / Aufschwung Ost | F52: 0'42" | G52: 123407 | H52: 89509
C53: 36280 | D53: SpätAbendschau | E53: Demonstrationen am Vorabend des 1. Mai | F53: 2'04" | G53: 126764 | H53: 99163
C54: 36647 | D54: SpätAbendschau | E54: DGB-Demonstration und -kundgebung zum 1. Mai | F54: 0'59" | G54: 128242 | H54: 102355
C55: 36647 | D55: SpätAbendschau | E55: Revolutionäre Mai-Demonstration in Kreuzberg | F55: 1'38" | G55: 128242 | H55: 102355
C56: 36647 | D56: SpätAbendschau | E56: NPD-Demonstration in Hellersdorf | F56: 2'45" | G56: 128242 | H56: 102355
C57: 37011 | D57: SpätAbendschau | E57: Walpurgisnacht und 1. Mai | F57: 1'18" | G57: 129710 | H57: 105171
C58: 37377 | D58: SpätAbendschau | E58: Aktuelle Abendereignisse am 1. Mai 2002 | F58: 1'45" | G58: 131170 | H58: 108353
C59: 37377 | D59: SpätAbendschau | E59: NPD-Demonstration | F59: 0'28" | G59: 131170 | H59: 108353
... C62: 37743 | D62: Abendschau | E62: Bilanz 1. Mai 2003 | F62: 2'15" | G62: 132634 | H62: 111306
C63: 39570 | D63: Abendschau | E63: Nachklapp 1. Mai | F63: 2'23" | G63: 2000144326 | H63: N/A
C64: 39934 | D64: Abendschau | E64: Off-Maz: 1. Mai in Berlin | F64: 0'28" | G64: 2000153239 | H64: N/A
C65: 40299 | D65: Abendschau | E65: Walpurgisnacht blieb eher ruhig | F65: 1'53" | G65: 6000000133 | H65: N/A
C66: 40663 | D66: Abendschau | E66: Liveschalte zur Walpurgisnacht im Mauerpark | F66: 4'33" | G66: 6000044022 | H66: N/A
C67: 40664 | D67: Abendschau | E67: Zusammenfassung Walpurgisnacht | F67: 1'28" | G67: 6000044116 | H67: N/A
C68: 41031 | D68: Abendschau | E68: Bilanz des 1. Mai | F68: 2'36" | G68: 6000058048 | H68: N/A
C69: 41394 | D69: Abendschau | E69: Anti-Nazi-Demo in Schöneweide | F69: 0'22" | G69: 6000072052 | H69: N/A
C70: 41761 | D70: Abendschau | E70: Nachklapp 1.Mai 2014 | F70: 1'34" | G70: 6000085766 | H70: N/A
...

Sheet Wykresy oddzielne prasa policja
A1: Rok | B1: Prasa | C1: Organizatorzy | D1: Policja | E1: Średnia ogólna | F1: średnia metoda alt | G1: Różnica % | H1: średnia ruchoma
A2: 1990 | B2: =IFERROR(AVERAGEIFS(Dane!$B$2:$B$116,Dane!$A$2:$A$116,$A2,Dane!$D$2:$D$116,"prasa"),"") -> 56666.667 | C2: =IFERROR(AVERAGEIFS(Dane!$B$2:$B$116,Dane!$A$2:$A$116,$A2,Dane!$D$2:$D$116,"organizatorzy"),"") | D2: =IFERROR(AVERAGEIFS(Dane!$B$2:$B$116,Dane!$A$2:$A$116,$A2,Dane!$D$2:$D$116,"policja"),"") | E2: =IFERROR((0.5*IF(B2<>"",B2,0) + 0.25*IF(C2<>"",C2,0) + 0.25*IF(D2<>"",D2,0))/(0.5*IF(B2<>"",1,0) + 0.25*IF(C2<>"",1,0) + 0.25*IF(D2<>"",1,0)),"") -> 56666.667 | F2: =IFERROR(AVERAGEIFS(Dane!$B$2:$B$116,Dane!$A$2:$A$116,$A2),"") -> 56666.667 | G2: =E2-F2 -> 0
A3: 1991 | B3: =IFERROR(AVERAGEIFS(Dane!$B$2:$B$116,Dane!$A$2:$A$116,$A3,Dane!$D$2:$D$116,"prasa"),"") -> 7500 | C3: =IFERROR(AVERAGEIFS(Dane!$B$2:$B$116,Dane!$A$2:$A$116,$A3,Dane!$D$2:$D$116,"organizatorzy"),"") -> 15000 | D3: =IFERROR(AVERAGEIFS(Dane!$B$2:$B$116,Dane!$A$2:$A$116,$A3,Dane!$D$2:$D$116,"policja"),"") | E3: =IFERROR((0.5*IF(B3<>"",B3,0) + 0.25*IF(C3<>"",C3,0) + 0.25*IF(D3<>"",D3,0))/(0.5*IF(B3<>"",1,0) + 0.25*IF(C3<>"",1,0) + 0.25*IF(D3<>"",1,0)),"") -> 10000 | F3: =IFERROR(AVERAGEIFS(Dane!$B$2:$B$116,Dane!$A$2:$A$116,$A3),"") -> 10000 | G3: =E3-F3 -> 0 | H3: =AVERAGE(F2:F4) -> 29888.889
A4: 1992 | B4: =IFERROR(AVERAGEIFS(Dane!$B$2:$B$116,Dane!$A$2:$A$116,$A4,Dane!$D$2:$D$116,"prasa"),"") -> 26250 | C4: =IFERROR(AVERAGEIFS(Dane!$B$2:$B$116,Dane!$A$2:$A$116,$A4,Dane!$D$2:$D$116,"organizatorzy"),"") -> 25000 | D4: =IFERROR(AVERAGEIFS(Dane!$B$2:$B$116,Dane!$A$2:$A$116,$A4,Dane!$D$2:$D$116,"policja"),"") -> 8000 | E4: =IFERROR((0.5*IF(B4<>"",B4,0) + 0.25*IF(C4<>"",C4,0) + 0.25*IF(D4<>"",D4,0))/(0.5*IF(B4<>"",1,0) + 0.25*IF(C4<>"",1,0) + 0.25*IF(D4<>"",1,0)),"") -> 21375 | F4: =IFERROR(AVERAGEIFS(Dane!$B$2:$B$116,Dane!$A$2:$A$116,$A4),"") -> 23000 | G4: =E4-F4 -> -1625 | H4: =AVERAGE(F3:F5) -> 16555.556
A5: 1993 | B5: =IFERROR(AVERAGEIFS(Dane!$B$2:$B$116,Dane!$A$2:$A$116,$A5,Dane!$D$2:$D$116,"prasa"),"") -> 10000 | C5: =IFERROR(AVERAGEIFS(Dane!$B$2:$B$116,Dane!$A$2:$A$116,$A5,Dane!$D$2:$D$116,"organizatorzy"),"") -> 30000 | D5: =IFERROR(AVERAGEIFS(Dane!$B$2:$B$116,Dane!$A$2:$A$116,$A5,Dane!$D$2:$D$116,"policja"),"") | E5: =IFERROR((0.5*IF(B5<>"",B5,0) + 0.25*IF(C5<>"",C5,0) + 0.25*IF(D5<>"",D5,0))/(0.5*IF(B5<>"",1,0) + 0.25*IF(C5<>"",1,0) + 0.25*IF(D5<>"",1,0)),"") -> 16666.667 | F5: =IFERROR(AVERAGEIFS(Dane!$B$2:$B$116,Dane!$A$2:$A$116,$A5),"") -> 16666.667 | G5: =E5-F5 -> 0 | H5: =AVERAGE(F4:F6) -> 15222.222
A6: 1994 | B6: =IFERROR(AVERAGEIFS(Dane!$B$2:$B$116,Dane!$A$2:$A$116,$A6,Dane!$D$2:$D$116,"prasa"),"") -> 5000 | C6: =IFERROR(AVERAGEIFS(Dane!$B$2:$B$116,Dane!$A$2:$A$116,$A6,Dane!$D$2:$D$116,"organizatorzy"),"") -> 8000 | D6: =IFERROR(AVERAGEIFS(Dane!$B$2:$B$116,Dane!$A$2:$A$116,$A6,Dane!$D$2:$D$116,"policja"),"") | E6: =IFERROR((0.5*IF(B6<>"",B6,0) + 0.25*IF(C6<>"",C6,0) + 0.25*IF(D6<>"",D6,0))/(0.5*IF(B6<>"",1,0) + 0.25*IF(C6<>"",1,0) + 0.25*IF(D6<>"",1,0)),"") -> 6000 | F6: =IFERROR(AVERAGEIFS(Dane!$B$2:$B$116,Dane!$A$2:$A$116,$A6),"") -> 6000 | G6: =E6-F6 -> 0 | H6: =AVERAGE(F5:F7) -> 10022.222
A7: 1995 | B7: =IFERROR(AVERAGEIFS(Dane!$B$2:$B$116,Dane!$A$2:$A$116,$A7,Dane!$D$2:$D$116,"prasa"),"") -> 6750 | C7: =IFERROR(AVERAGEIFS(Dane!$B$2:$B$116,Dane!$A$2:$A$116,$A7,Dane!$D$2:$D$116,"organizatorzy"),"") -> 10000 | D7: =IFERROR(AVERAGEIFS(Dane!$B$2:$B$116,Dane!$A$2:$A$116,$A7,Dane!$D$2:$D$116,"policja"),"") | E7: =IFERROR((0.5*IF(B7<>"",B7,0) + 0.25*IF(C7<>"",C7,0) + 0.25*IF(D7<>"",D7,0))/(0.5*IF(B7<>"",1,0) + 0.25*IF(C7<>"",1,0) + 0.25*IF(D7<>"",1,0)),"") -> 7833.3333 | F7: =IFERROR(AVERAGEIFS(Dane!$B$2:$B$116,Dane!$A$2:$A$116,$A7),"") -> 7400 | G7: =E7-F7 -> 433.33333 | H7: =AVERAGE(F6:F8) -> 10022.222
A8: 1996 | B8: =IFERROR(AVERAGEIFS(Dane!$B$2:$B$116,Dane!$A$2:$A$116,$A8,Dane!$D$2:$D$116,"prasa"),"") -> 16666.667 | C8: =AVERAGE(C7,C9) -> 17500 | D8: =IFERROR(AVERAGEIFS(Dane!$B$2:$B$116,Dane!$A$2:$A$116,$A8,Dane!$D$2:$D$116,"policja"),"") | E8: =IFERROR((0.5*IF(B8<>"",B8,0) + 0.25*IF(C8<>"",C8,0) + 0.25*IF(D8<>"",D8,0))/(0.5*IF(B8<>"",1,0) + 0.25*IF(C8<>"",1,0) + 0.25*IF(D8<>"",1,0)),"") -> 16944.444 | F8: =IFERROR(AVERAGEIFS(Dane!$B$2:$B$116,Dane!$A$2:$A$116,$A8),"") -> 16666.667 | G8: =E8-F8 -> 277.77778 | H8: =AVERAGE(F7:F9) -> 11188.889
A9: 1997 | B9: =IFERROR(AVERAGEIFS(Dane!$B$2:$B$116,Dane!$A$2:$A$116,$A9,Dane!$D$2:$D$116,"prasa"),"") -> 5833.3333 | C9: =IFERROR(AVERAGEIFS(Dane!$B$2:$B$116,Dane!$A$2:$A$116,$A9,Dane!$D$2:$D$116,"organizatorzy"),"") -> 25000 | D9: =IFERROR(AVERAGEIFS(Dane!$B$2:$B$116,Dane!$A$2:$A$116,$A9,Dane!$D$2:$D$116,"policja"),"") -> 5000 | E9: =IFERROR((0.5*IF(B9<>"",B9,0) + 0.25*IF(C9<>"",C9,0) + 0.25*IF(D9<>"",D9,0))/(0.5*IF(B9<>"",1,0) + 0.25*IF(C9<>"",1,0) + 0.25*IF(D9<>"",1,0)),"") -> 10416.667 | F9: =IFERROR(AVERAGEIFS(Dane!$B$2:$B$116,Dane!$A$2:$A$116,$A9),"") -> 9500 | G9: =E9-F9 -> 916.66667 | H9: =AVERAGE(F8:F10) -> 13347.222
A10: 1998 | B10: =IFERROR(AVERAGEIFS(Dane!$B$2:$B$116,Dane!$A$2:$A$116,$A10,Dane!$D$2:$D$116,"prasa"),"") -> 12666.667 | C10: =IFERROR(AVERAGEIFS(Dane!$B$2:$B$116,Dane!$A$2:$A$116,$A10,Dane!$D$2:$D$116,"organizatorzy"),"") -> 17500 | D10: =IFERROR(AVERAGEIFS(Dane!$B$2:$B$116,Dane!$A$2:$A$116,$A10,Dane!$D$2:$D$116,"policja"),"") | E10: =IFERROR((0.5*IF(B10<>"",B10,0) + 0.25*IF(C10<>"",C10,0) + 0.25*IF(D10<>"",D10,0))/(0.5*IF(B10<>"",1,0) + 0.25*IF(C10<>"",1,0) + 0.25*IF(D10<>"",1,0)),"") -> 14277.778 | F10: =IFERROR(AVERAGEIFS(Dane!$B$2:$B$116,Dane!$A$2:$A$116,$A10),"") -> 13875 | G10: =E10-F10 -> 402.77778 | H10: =AVERAGE(F9:F11) -> 11258.333
A11: 1999 | B11: =IFERROR(AVERAGEIFS(Dane!$B$2:$B$116,Dane!$A$2:$A$116,$A11,Dane!$D$2:$D$116,"prasa"),"") -> 10000 | C11: =IFERROR(AVERAGEIFS(Dane!$B$2:$B$116,Dane!$A$2:$A$116,$A11,Dane!$D$2:$D$116,"organizatorzy"),"") -> 15000 | D11: =IFERROR(AVERAGEIFS(Dane!$B$2:$B$116,Dane!$A$2:$A$116,$A11,Dane!$D$2:$D$116,"policja"),"") -> 7000 | E11: =IFERROR((0.5*IF(B11<>"",B11,0) + 0.25*IF(C11<>"",C11,0) + 0.25*IF(D11<>"",D11,0))/(0.5*IF(B11<>"",1,0) + 0.25*IF(C11<>"",1,0) + 0.25*IF(D11<>"",1,0)),"") -> 10500 | F11: =IFERROR(AVERAGEIFS(Dane!$B$2:$B$116,Dane!$A$2:$A$116,$A11),"") -> 10400 | G11: =E11-F11 -> 100 | H11: =AVERAGE(F10:F12) -> 11813.889
A12: 2000 | B12: =IFERROR(AVERAGEIFS(Dane!$B$2:$B$116,Dane!$A$2:$A$116,$A12,Dane!$D$2:$D$116,"prasa"),"") -> 10000 | C12: =IFERROR(AVERAGEIFS(Dane!$B$2:$B$116,Dane!$A$2:$A$116,$A12,Dane!$D$2:$D$116,"organizatorzy"),"") -> 15000 | D12: =IFERROR(AVERAGEIFS(Dane!$B$2:$B$116,Dane!$A$2:$A$116,$A12,Dane!$D$2:$D$116,"policja"),"") -> 7000 | E12: =IFERROR((0.5*IF(B12<>"",B12,0) + 0.25*IF(C12<>"",C12,0) + 0.25*IF(D12<>"",D12,0))/(0.5*IF(B12<>"",1,0) + 0.25*IF(C12<>"",1,0) + 0.25*IF(D12<>"",1,0)),"") -> 10500 | F12: =IFERROR(AVERAGEIFS(Dane!$B$2:$B$116,Dane!$A$2:$A$116,$A12),"") -> 11166.667 | G12: =E12-F12 -> -666.66667 | H12: =AVERAGE(F11:F13) -> 12800
A13: 2001 | B13: =IFERROR(AVERAGEIFS(Dane!$B$2:$B$116,Dane!$A$2:$A$116,$A13,Dane!$D$2:$D$116,"prasa"),"") -> 16833.333 | C13: =AVERAGE(C12,C14) -> 20000 | D13: =IFERROR(AVERAGEIFS(Dane!$B$2:$B$116,Dane!$A$2:$A$116,$A13,Dane!$D$2:$D$116,"policja"),"") | E13: =IFERROR((0.5*IF(B13<>"",B13,0) + 0.25*IF(C13<>"",C13,0) + 0.25*IF(D13<>"",D13,0))/(0.5*IF(B13<>"",1,0) + 0.25*IF(C13<>"",1,0) + 0.25*IF(D13<>"",1,0)),"") -> 17888.889 | F13: =IFERROR(AVERAGEIFS(Dane!$B$2:$B$116,Dane!$A$2:$A$116,$A13),"") -> 16833.333 | G13: =E13-F13 -> 1055.5556 | H13: =AVERAGE(F12:F14) -> 13833.333
A14: 2002 | B14: =IFERROR(AVERAGEIFS(Dane!$B$2:$B$116,Dane!$A$2:$A$116,$A14,Dane!$D$2:$D$116,"prasa"),"") -> 11000 | C14: =IFERROR(AVERAGEIFS(Dane!$B$2:$B$116,Dane!$A$2:$A$116,$A14,Dane!$D$2:$D$116,"organizatorzy"),"") -> 25000 | D14: =IFERROR(AVERAGEIFS(Dane!$B$2:$B$116,Dane!$A$2:$A$116,$A14,Dane!$D$2:$D$116,"policja"),"") -> 7000 | E14: =IFERROR((0.5*IF(B14<>"",B14,0) + 0.25*IF(C14<>"",C14,0) + 0.25*IF(D14<>"",D14,0))/(0.5*IF(B14<>"",1,0) + 0.25*IF(C14<>"",1,0) + 0.25*IF(D14<>"",1,0)),"") -> 13500 | F14: =IFERROR(AVERAGEIFS(Dane!$B$2:$B$116,Dane!$A$2:$A$116,$A14),"") -> 13500 | G14: =E14-F14 -> 0 | H14: =AVERAGE(F13:F15) -> 14611.111
A15: 2003 | B15: =IFERROR(AVERAGEIFS(Dane!$B$2:$B$116,Dane!$A$2:$A$116,$A15,Dane!$D$2:$D$116,"prasa"),"") | C15: =IFERROR(AVERAGEIFS(Dane!$B$2:$B$116,Dane!$A$2:$A$116,$A15,Dane!$D$2:$D$116,"organizatorzy"),"") -> 20000 | D15: =IFERROR(AVERAGEIFS(Dane!$B$2:$B$116,Dane!$A$2:$A$116,$A15,Dane!$D$2:$D$116,"policja"),"") -> 7000 | E15: =IFERROR((0.5*IF(B15<>"",B15,0) + 0.25*IF(C15<>"",C15,0) + 0.25*IF(D15<>"",D15,0))/(0.5*IF(B15<>"",1,0) + 0.25*IF(C15<>"",1,0) + 0.25*IF(D15<>"",1,0)),"") -> 13500 | F15: =IFERROR(AVERAGEIFS(Dane!$B$2:$B$116,Dane!$A$2:$A$116,$A15),"") -> 13500 | G15: =E15-F15 -> 0 | H15: =AVERAGE(F14:F16) -> 15166.667
A16: 2004 | B16: =IFERROR(AVERAGEIFS(Dane!$B$2:$B$116,Dane!$A$2:$A$116,$A16,Dane!$D$2:$D$116,"prasa"),"") | C16: =IFERROR(AVERAGEIFS(Dane!$B$2:$B$116,Dane!$A$2:$A$116,$A16,Dane!$D$2:$D$116,"organizatorzy"),"") -> 25000 | D16: =IFERROR(AVERAGEIFS(Dane!$B$2:$B$116,Dane!$A$2:$A$116,$A16,Dane!$D$2:$D$116,"policja"),"") -> 12000 | E16: =IFERROR((0.5*IF(B16<>"",B16,0) + 0.25*IF(C16<>"",C16,0) + 0.25*IF(D16<>"",D16,0))/(0.5*IF(B16<>"",1,0) + 0.25*IF(C16<>"",1,0) + 0.25*IF(D16<>"",1,0)),"") -> 18500 | F16: =IFERROR(AVERAGEIFS(Dane!$B$2:$B$116,Dane!$A$2:$A$116,$A16),"") -> 18500 | G16: =E16-F16 -> 0 | H16: =AVERAGE(F15:F17) -> 14166.667
A17: 2005 | B17: =IFERROR(AVERAGEIFS(Dane!$B$2:$B$116,Dane!$A$2:$A$116,$A17,Dane!$D$2:$D$116,"prasa"),"") -> 10000 | C17: =IFERROR(AVERAGEIFS(Dane!$B$2:$B$116,Dane!$A$2:$A$116,$A17,Dane!$D$2:$D$116,"organizatorzy"),"") -> 12000 | D17: =IFERROR(AVERAGEIFS(Dane!$B$2:$B$116,Dane!$A$2:$A$116,$A17,Dane!$D$2:$D$116,"policja"),"") | E17: =IFERROR((0.5*IF(B17<>"",B17,0) + 0.25*IF(C17<>"",C17,0) + 0.25*IF(D17<>"",D17,0))/(0.5*IF(B17<>"",1,0) + 0.25*IF(C17<>"",1,0) + 0.25*IF(D17<>"",1,0)),"") -> 10666.667 | F17: =IFERROR(AVERAGEIFS(Dane!$B$2:$B$116,Dane!$A$2:$A$116,$A17),"") -> 10500 | G17: =E17-F17 -> 166.66667 | H17: =AVERAGE(F16:F18) -> 14166.667
A18: 2006 | B18: =IFERROR(AVERAGEIFS(Dane!$B$2:$B$116,Dane!$A$2:$A$116,$A18,Dane!$D$2:$D$116,"prasa"),"") -> 9000 | C18: =IFERROR(AVERAGEIFS(Dane!$B$2:$B$116,Dane!$A$2:$A$116,$A18,Dane!$D$2:$D$116,"organizatorzy"),"") -> 21000 | D18: =IFERROR(AVERAGEIFS(Dane!$B$2:$B$116,Dane!$A$2:$A$116,$A18,Dane!$D$2:$D$116,"policja"),"") -> 7500 | E18: =IFERROR((0.5*IF(B18<>"",B18,0) + 0.25*IF(C18<>"",C18,0) + 0.25*IF(D18<>"",D18,0))/(0.5*IF(B18<>"",1,0) + 0.25*IF(C18<>"",1,0) + 0.25*IF(D18<>"",1,0)),"") -> 11625 | F18: =IFERROR(AVERAGEIFS(Dane!$B$2:$B$116,Dane!$A$2:$A$116,$A18),"") -> 13500 | G18: =E18-F18 -> -1875 | H18: =AVERAGE(F17:F19) -> 11500
A19: 2007 | B19: =IFERROR(AVERAGEIFS(Dane!$B$2:$B$116,Dane!$A$2:$A$116,$A19,Dane!$D$2:$D$116,"prasa"),"") -> 12000 | C19: =IFERROR(AVERAGEIFS(Dane!$B$2:$B$116,Dane!$A$2:$A$116,$A19,Dane!$D$2:$D$116,"organizatorzy"),"") -> 12000 | D19: =IFERROR(AVERAGEIFS(Dane!$B$2:$B$116,Dane!$A$2:$A$116,$A19,Dane!$D$2:$D$116,"policja"),"") -> 7500 | E19: =IFERROR((0.5*IF(B19<>"",B19,0) + 0.25*IF(C19<>"",C19,0) + 0.25*IF(D19<>"",D19,0))/(0.5*IF(B19<>"",1,0) + 0.25*IF(C19<>"",1,0) + 0.25*IF(D19<>"",1,0)),"") -> 10875 | F19: =IFERROR(AVERAGEIFS(Dane!$B$2:$B$116,Dane!$A$2:$A$116,$A19),"") -> 10500 | G19: =E19-F19 -> 375 | H19: =AVERAGE(F18:F20) -> 11041.667
A20: 2008 | B20: =IFERROR(AVERAGEIFS(Dane!$B$2:$B$116,Dane!$A$2:$A$116,$A20,Dane!$D$2:$D$116,"prasa"),"") -> 5750 | C20: =IFERROR(AVERAGEIFS(Dane!$B$2:$B$116,Dane!$A$2:$A$116,$A20,Dane!$D$2:$D$116,"organizatorzy"),"") -> 20000 | D20: =IFERROR(AVERAGEIFS(Dane!$B$2:$B$116,Dane!$A$2:$A$116,$A20,Dane!$D$2:$D$116,"policja"),"") -> 5000 | E20: =IFERROR((0.5*IF(B20<>"",B20,0) + 0.25*IF(C20<>"",C20,0) + 0.25*IF(D20<>"",D20,0))/(0.5*IF(B20<>"",1,0) + 0.25*IF(C20<>"",1,0) + 0.25*IF(D20<>"",1,0)),"") -> 9125 | F20: =IFERROR(AVERAGEIFS(Dane!$B$2:$B$116,Dane!$A$2:$A$116,$A20),"") -> 9125 | G20: =E20-F20 -> 0 | H20: =AVERAGE(F19:F21) -> 11041.667
A21: 2009 | B21: =IFERROR(AVERAGEIFS(Dane!$B$2:$B$116,Dane!$A$2:$A$116,$A21,Dane!$D$2:$D$116,"prasa"),"") | C21: =IFERROR(AVERAGEIFS(Dane!$B$2:$B$116,Dane!$A$2:$A$116,$A21,Dane!$D$2:$D$116,"organizatorzy"),"") -> 19000 | D21: =IFERROR(AVERAGEIFS(Dane!$B$2:$B$116,Dane!$A$2:$A$116,$A21,Dane!$D$2:$D$116,"policja"),"") -> 2500 | E21: =IFERROR((0.5*IF(B21<>"",B21,0) + 0.25*IF(C21<>"",C21,0) + 0.25*IF(D21<>"",D21,0))/(0.5*IF(B21<>"",1,0) + 0.25*IF(C21<>"",1,0) + 0.25*IF(D21<>"",1,0)),"") -> 10750 | F21: =IFERROR(AVERAGEIFS(Dane!$B$2:$B$116,Dane!$A$2:$A$116,$A21),"") -> 13500 | G21: =E21-F21 -> -2750 | H21: =AVERAGE(F20:F22) -> 10791.667
A22: 2010 | B22: =IFERROR(AVERAGEIFS(Dane!$B$2:$B$116,Dane!$A$2:$A$116,$A22,Dane!$D$2:$D$116,"prasa"),"") | C22: =IFERROR(AVERAGEIFS(Dane!$B$2:$B$116,Dane!$A$2:$A$116,$A22,Dane!$D$2:$D$116,"organizatorzy"),"") -> 12000 | D22: =IFERROR(AVERAGEIFS(Dane!$B$2:$B$116,Dane!$A$2:$A$116,$A22,Dane!$D$2:$D$116,"policja"),"") -> 7500 | E22: =IFERROR((0.5*IF(B22<>"",B22,0) + 0.25*IF(C22<>"",C22,0) + 0.25*IF(D22<>"",D22,0))/(0.5*IF(B22<>"",1,0) + 0.25*IF(C22<>"",1,0) + 0.25*IF(D22<>"",1,0)),"") -> 9750 | F22: =IFERROR(AVERAGEIFS(Dane!$B$2:$B$116,Dane!$A$2:$A$116,$A22),"") -> 9750 | G22: =E22-F22 -> 0 | H22: =AVERAGE(F21:F23) -> 11583.333
A23: 2011 | B23: =IFERROR(AVERAGEIFS(Dane!$B$2:$B$116,Dane!$A$2:$A$116,$A23,Dane!$D$2:$D$116,"prasa"),"") -> 15000 | C23: =IFERROR(AVERAGEIFS(Dane!$B$2:$B$116,Dane!$A$2:$A$116,$A23,Dane!$D$2:$D$116,"organizatorzy"),"") -> 12500 | D23: =IFERROR(AVERAGEIFS(Dane!$B$2:$B$116,Dane!$A$2:$A$116,$A23,Dane!$D$2:$D$116,"policja"),"") -> 6000 | E23: =IFERROR((0.5*IF(B23<>"",B23,0) + 0.25*IF(C23<>"",C23,0) + 0.25*IF(D23<>"",D23,0))/(0.5*IF(B23<>"",1,0) + 0.25*IF(C23<>"",1,0) + 0.25*IF(D23<>"",1,0)),"") -> 12125 | F23: =IFERROR(AVERAGEIFS(Dane!$B$2:$B$116,Dane!$A$2:$A$116,$A23),"") -> 11500 | G23: =E23-F23 -> 625 | H23: =AVERAGE(F22:F24) -> 11291.667
A24: 2012 | B24: =IFERROR(AVERAGEIFS(Dane!$B$2:$B$116,Dane!$A$2:$A$116,$A24,Dane!$D$2:$D$116,"prasa"),"") -> 11833.333 | C24: =IFERROR(AVERAGEIFS(Dane!$B$2:$B$116,Dane!$A$2:$A$116,$A24,Dane!$D$2:$D$116,"organizatorzy"),"") -> 15000 | D24: =IFERROR(AVERAGEIFS(Dane!$B$2:$B$116,Dane!$A$2:$A$116,$A24,Dane!$D$2:$D$116,"policja"),"") | E24: =IFERROR((0.5*IF(B24<>"",B24,0) + 0.25*IF(C24<>"",C24,0) + 0.25*IF(D24<>"",D24,0))/(0.5*IF(B24<>"",1,0) + 0.25*IF(C24<>"",1,0) + 0.25*IF(D24<>"",1,0)),"") -> 12888.889 | F24: =IFERROR(AVERAGEIFS(Dane!$B$2:$B$116,Dane!$A$2:$A$116,$A24),"") -> 12625 | G24: =E24-F24 -> 263.88889 | H24: =AVERAGE(F23:F25) -> 11291.667
A25: 2013 | B25: =IFERROR(AVERAGEIFS(Dane!$B$2:$B$116,Dane!$A$2:$A$116,$A25,Dane!$D$2:$D$116,"prasa"),"") -> 9750 | C25: =AVERAGE(C24,C26) -> 15000 | D25: =IFERROR(AVERAGEIFS(Dane!$B$2:$B$116,Dane!$A$2:$A$116,$A25,Dane!$D$2:$D$116,"policja"),"") | E25: =IFERROR((0.5*IF(B25<>"",B25,0) + 0.25*IF(C25<>"",C25,0) + 0.25*IF(D25<>"",D25,0))/(0.5*IF(B25<>"",1,0) + 0.25*IF(C25<>"",1,0) + 0.25*IF(D25<>"",1,0)),"") -> 11500 | F25: =IFERROR(AVERAGEIFS(Dane!$B$2:$B$116,Dane!$A$2:$A$116,$A25),"") -> 9750 | G25: =E25-F25 -> 1750 | H25: =AVERAGE(F24:F26) -> 10791.667
A26: 2014 | B26: =IFERROR(AVERAGEIFS(Dane!$B$2:$B$116,Dane!$A$2:$A$116,$A26,Dane!$D$2:$D$116,"prasa"),"") -> 10000 | C26: 15000 | D26: =IFERROR(AVERAGEIFS(Dane!$B$2:$B$116,Dane!$A$2:$A$116,$A26,Dane!$D$2:$D$116,"policja"),"") | E26: =IFERROR((0.5*IF(B26<>"",B26,0) + 0.25*IF(C26<>"",C26,0) + 0.25*IF(D26<>"",D26,0))/(0.5*IF(B26<>"",1,0) + 0.25*IF(C26<>"",1,0) + 0.25*IF(D26<>"",1,0)),"") -> 11666.667 | F26: =IFERROR(AVERAGEIFS(Dane!$B$2:$B$116,Dane!$A$2:$A$116,$A26),"") -> 10000 | G26: =E26-F26 -> 1666.6667 | H26: =AVERAGE(F25:F27) -> 11583.333
A27: 2015 | B27: =IFERROR(AVERAGEIFS(Dane!$B$2:$B$116,Dane!$A$2:$A$116,$A27,Dane!$D$2:$D$116,"prasa"),"") | C27: =IFERROR(AVERAGEIFS(Dane!$B$2:$B$116,Dane!$A$2:$A$116,$A27,Dane!$D$2:$D$116,"organizatorzy"),"") -> 15000 | D27: =IFERROR(AVERAGEIFS(Dane!$B$2:$B$116,Dane!$A$2:$A$116,$A27,Dane!$D$2:$D$116,"policja"),"") | E27: =IFERROR((0.5*IF(B27<>"",B27,0) + 0.25*IF(C27<>"",C27,0) + 0.25*IF(D27<>"",D27,0))/(0.5*IF(B27<>"",1,0) + 0.25*IF(C27<>"",1,0) + 0.25*IF(D27<>"",1,0)),"") -> 15000 | F27: =IFERROR(AVERAGEIFS(Dane!$B$2:$B$116,Dane!$A$2:$A$116,$A27),"") -> 15000 | G27: =E27-F27 -> 0 | H27: =AVERAGE(F26:F28) -> 13000
A28: 2016 | B28: =IFERROR(AVERAGEIFS(Dane!$B$2:$B$116,Dane!$A$2:$A$116,$A28,Dane!$D$2:$D$116,"prasa"),"") | C28: =IFERROR(AVERAGEIFS(Dane!$B$2:$B$116,Dane!$A$2:$A$116,$A28,Dane!$D$2:$D$116,"organizatorzy"),"") -> 14000 | D28: =IFERROR(AVERAGEIFS(Dane!$B$2:$B$116,Dane!$A$2:$A$116,$A28,Dane!$D$2:$D$116,"policja"),"") | E28: =IFERROR((0.5*IF(B28<>"",B28,0) + 0.25*IF(C28<>"",C28,0) + 0.25*IF(D28<>"",D28,0))/(0.5*IF(B28<>"",1,0) + 0.25*IF(C28<>"",1,0) + 0.25*IF(D28<>"",1,0)),"") -> 14000 | F28: =IFERROR(AVERAGEIFS(Dane!$B$2:$B$116,Dane!$A$2:$A$116,$A28),"") -> 14000 | G28: =E28-F28 -> 0 | H28: =AVERAGE(F27:F29) -> 14333.333
A29: 2017 | B29: =IFERROR(AVERAGEIFS(Dane!$B$2:$B$116,Dane!$A$2:$A$116,$A29,Dane!$D$2:$D$116,"prasa"),"") | C29: =IFERROR(AVERAGEIFS(Dane!$B$2:$B$116,Dane!$A$2:$A$116,$A29,Dane!$D$2:$D$116,"organizatorzy"),"") -> 14000 | D29: =IFERROR(AVERAGEIFS(Dane!$B$2:$B$116,Dane!$A$2:$A$116,$A29,Dane!$D$2:$D$116,"policja"),"") | E29: =IFERROR((0.5*IF(B29<>"",B29,0) + 0.25*IF(C29<>"",C29,0) + 0.25*IF(D29<>"",D29,0))/(0.5*IF(B29<>"",1,0) + 0.25*IF(C29<>"",1,0) + 0.25*IF(D29<>"",1,0)),"") -> 14000 | F29: =IFERROR(AVERAGEIFS(Dane!$B$2:$B$116,Dane!$A$2:$A$116,$A29),"") -> 14000 | G29: =E29-F29 -> 0 | H29: =AVERAGE(F28:F30) -> 12500
A30: 2018 | B30: =IFERROR(AVERAGEIFS(Dane!$B$2:$B$116,Dane!$A$2:$A$116,$A30,Dane!$D$2:$D$116,"prasa"),"") | C30: =IFERROR(AVERAGEIFS(Dane!$B$2:$B$116,Dane!$A$2:$A$116,$A30,Dane!$D$2:$D$116,"organizatorzy"),"") -> 14000 | D30: =IFERROR(AVERAGEIFS(Dane!$B$2:$B$116,Dane!$A$2:$A$116,$A30,Dane!$D$2:$D$116,"policja"),"") -> 5000 | E30: =IFERROR((0.5*IF(B30<>"",B30,0) + 0.25*IF(C30<>"",C30,0) + 0.25*IF(D30<>"",D30,0))/(0.5*IF(B30<>"",1,0) + 0.25*IF(C30<>"",1,0) + 0.25*IF(D30<>"",1,0)),"") -> 9500 | F30: =IFERROR(AVERAGEIFS(Dane!$B$2:$B$116,Dane!$A$2:$A$116,$A30),"") -> 9500 | G30: =E30-F30 -> 0 | H30: =AVERAGE(F29:F31) -> 12166.667
A31: 2019 | B31: =IFERROR(AVERAGEIFS(Dane!$B$2:$B$116,Dane!$A$2:$A$116,$A31,Dane!$D$2:$D$116,"prasa"),"") | C31: =IFERROR(AVERAGEIFS(Dane!$B$2:$B$116,Dane!$A$2:$A$116,$A31,Dane!$D$2:$D$116,"organizatorzy"),"") -> 13000 | D31: =IFERROR(AVERAGEIFS(Dane!$B$2:$B$116,Dane!$A$2:$A$116,$A31,Dane!$D$2:$D$116,"policja"),"") | E31: =IFERROR((0.5*IF(B31<>"",B31,0) + 0.25*IF(C31<>"",C31,0) + 0.25*IF(D31<>"",D31,0))/(0.5*IF(B31<>"",1,0) + 0.25*IF(C31<>"",1,0) + 0.25*IF(D31<>"",1,0)),"") -> 13000 | F31: =IFERROR(AVERAGEIFS(Dane!$B$2:$B$116,Dane!$A$2:$A$116,$A31),"") -> 13000 | G31: =E31-F31 -> 0 | H31: =AVERAGE(F30:F32) -> 7500
A32: 2020 | B32: =IFERROR(AVERAGEIFS(Dane!$B$2:$B$116,Dane!$A$2:$A$116,$A32,Dane!$D$2:$D$116,"prasa"),"") | C32: =IFERROR(AVERAGEIFS(Dane!$B$2:$B$116,Dane!$A$2:$A$116,$A32,Dane!$D$2:$D$116,"organizatorzy"),"") | D32: =IFERROR(AVERAGEIFS(Dane!$B$2:$B$116,Dane!$A$2:$A$116,$A32,Dane!$D$2:$D$116,"policja"),"") | E32: =IFERROR((0.5*IF(B32<>"",B32,0) + 0.25*IF(C32<>"",C32,0) + 0.25*IF(D32<>"",D32,0))/(0.5*IF(B32<>"",1,0) + 0.25*IF(C32<>"",1,0) + 0.25*IF(D32<>"",1,0)),"") | F32: =IFERROR(AVERAGEIFS(Dane!$B$2:$B$116,Dane!$A$2:$A$116,$A32),"") -> 0 | G32: =E32-F32 -> 0 | H32: =AVERAGE(F31:F33) -> 4433.3333
A33: 2021 | B33: =IFERROR(AVERAGEIFS(Dane!$B$2:$B$116,Dane!$A$2:$A$116,$A33,Dane!$D$2:$D$116,"prasa"),"") | C33: =IFERROR(AVERAGEIFS(Dane!$B$2:$B$116,Dane!$A$2:$A$116,$A33,Dane!$D$2:$D$116,"organizatorzy"),"") -> 300 | D33: =IFERROR(AVERAGEIFS(Dane!$B$2:$B$116,Dane!$A$2:$A$116,$A33,Dane!$D$2:$D$116,"policja"),"") | E33: =IFERROR((0.5*IF(B33<>"",B33,0) + 0.25*IF(C33<>"",C33,0) + 0.25*IF(D33<>"",D33,0))/(0.5*IF(B33<>"",1,0) + 0.25*IF(C33<>"",1,0) + 0.25*IF(D33<>"",1,0)),"") -> 300 | F33: =IFERROR(AVERAGEIFS(Dane!$B$2:$B$116,Dane!$A$2:$A$116,$A33),"") -> 300 | G33: =E33-F33 -> 0 | H33: =AVERAGE(F32:F34) -> 2933.3333
A34: 2022 | B34: =IFERROR(AVERAGEIFS(Dane!$B$2:$B$116,Dane!$A$2:$A$116,$A34,Dane!$D$2:$D$116,"prasa"),"") -> 7500 | C34: =IFERROR(AVERAGEIFS(Dane!$B$2:$B$116,Dane!$A$2:$A$116,$A34,Dane!$D$2:$D$116,"organizatorzy"),"") | D34: =IFERROR(AVERAGEIFS(Dane!$B$2:$B$116,Dane!$A$2:$A$116,$A34,Dane!$D$2:$D$116,"policja"),"") -> 9500 | E34: =IFERROR((0.5*IF(B34<>"",B34,0) + 0.25*IF(C34<>"",C34,0) + 0.25*IF(D34<>"",D34,0))/(0.5*IF(B34<>"",1,0) + 0.25*IF(C34<>"",1,0) + 0.25*IF(D34<>"",1,0)),"") -> 8166.6667 | F34: =IFERROR(AVERAGEIFS(Dane!$B$2:$B$116,Dane!$A$2:$A$116,$A34),"") -> 8500 | G34: =E34-F34 -> -333.33333 | H34: =AVERAGE(F33:F35) -> 4933.3333
A35: 2023 | B35: =IFERROR(AVERAGEIFS(Dane!$B$2:$B$116,Dane!$A$2:$A$116,$A35,Dane!$D$2:$D$116,"prasa"),"") | C35: =IFERROR(AVERAGEIFS(Dane!$B$2:$B$116,Dane!$A$2:$A$116,$A35,Dane!$D$2:$D$116,"organizatorzy"),"") | D35: =IFERROR(AVERAGEIFS(Dane!$B$2:$B$116,Dane!$A$2:$A$116,$A35,Dane!$D$2:$D$116,"policja"),"") -> 6000 | E35: =IFERROR((0.5*IF(B35<>"",B35,0) + 0.25*IF(C35<>"",C35,0) + 0.25*IF(D35<>"",D35,0))/(0.5*IF(B35<>"",1,0) + 0.25*IF(C35<>"",1,0) + 0.25*IF(D35<>"",1,0)),"") -> 6000 | F35: =IFERROR(AVERAGEIFS(Dane!$B$2:$B$116,Dane!$A$2:$A$116,$A35),"") -> 6000 | G35: =E35-F35 -> 0 | H35: =AVERAGE(F34:F36) -> 8611.1111
A36: 2024 | B36: =IFERROR(AVERAGEIFS(Dane!$B$2:$B$116,Dane!$A$2:$A$116,$A36,Dane!$D$2:$D$116,"prasa"),"") -> 10000 | C36: =IFERROR(AVERAGEIFS(Dane!$B$2:$B$116,Dane!$A$2:$A$116,$A36,Dane!$D$2:$D$116,"organizatorzy"),"") | D36: =IFERROR(AVERAGEIFS(Dane!$B$2:$B$116,Dane!$A$2:$A$116,$A36,Dane!$D$2:$D$116,"policja"),"") -> 14000 | E36: =IFERROR((0.5*IF(B36<>"",B36,0) + 0.25*IF(C36<>"",C36,0) + 0.25*IF(D36<>"",D36,0))/(0.5*IF(B36<>"",1,0) + 0.25*IF(C36<>"",1,0) + 0.25*IF(D36<>"",1,0)),"") -> 11333.333 | F36: =IFERROR(AVERAGEIFS(Dane!$B$2:$B$116,Dane!$A$2:$A$116,$A36),"") -> 11333.333 | G36: =E36-F36 -> 0 | H36: =AVERAGE(F35:F37) -> 8711.1111
A37: 2025 | B37: =IFERROR(AVERAGEIFS(Dane!$B$2:$B$116,Dane!$A$2:$A$116,$A37,Dane!$D$2:$D$116,"prasa"),"") -> 11000 | C37: =IFERROR(AVERAGEIFS(Dane!$B$2:$B$116,Dane!$A$2:$A$116,$A37,Dane!$D$2:$D$116,"organizatorzy"),"") | D37: =IFERROR(AVERAGEIFS(Dane!$B$2:$B$116,Dane!$A$2:$A$116,$A37,Dane!$D$2:$D$116,"policja"),"") -> 6600 | E37: =IFERROR((0.5*IF(B37<>"",B37,0) + 0.25*IF(C37<>"",C37,0) + 0.25*IF(D37<>"",D37,0))/(0.5*IF(B37<>"",1,0) + 0.25*IF(C37<>"",1,0) + 0.25*IF(D37<>"",1,0)),"") -> 9533.3333 | F37: =IFERROR(AVERAGEIFS(Dane!$B$2:$B$116,Dane!$A$2:$A$116,$A37),"") -> 8800 | G37: =E37-F37 -> 733.33333 | H37: =AVERAGE(F36:F38) -> 9894.4444
A38: 2026 | B38: =IFERROR(AVERAGEIFS(Dane!$B$2:$B$116,Dane!$A$2:$A$116,$A38,Dane!$D$2:$D$116,"prasa"),"") | C38: =IFERROR(AVERAGEIFS(Dane!$B$2:$B$116,Dane!$A$2:$A$116,$A38,Dane!$D$2:$D$116,"organizatorzy"),"") -> 12000 | D38: =IFERROR(AVERAGEIFS(Dane!$B$2:$B$116,Dane!$A$2:$A$116,$A38,Dane!$D$2:$D$116,"policja"),"") -> 7100 | E38: =IFERROR((0.5*IF(B38<>"",B38,0) + 0.25*IF(C38<>"",C38,0) + 0.25*IF(D38<>"",D38,0))/(0.5*IF(B38<>"",1,0) + 0.25*IF(C38<>"",1,0) + 0.25*IF(D38<>"",1,0)),"") -> 9550 | F38: =IFERROR(AVERAGEIFS(Dane!$B$2:$B$116,Dane!$A$2:$A$116,$A38),"") -> 9550 | G38: =E38-F38 -> 0

Sheet Dane_Revo
A1: Rok | B1: Liczba uczestników | C1: Źródło | D1: Kategoria | E1: Dane R1M 18
A2: 1996 | B2: 10000 | C2: Gluckspilz | D2: prasa
A3: 1997 | B3: 9000 | C3: Glückspilz | D3: prasa
A4: 1998 | B4: 3000 | C4: ND | D4: prasa
A5: 1998 | B5: 6000 | C5: Gluckspilz | D5: policja
A6: 1998 | B6: 11000 | C6: Gluckspilz | D6: organizatorzy
A7: 1999 | B7: 12000 | C7: Tagesspiegel | D7: prasa
A8: 1999 | B8: 15000 | C8: Gluckspilz | D8: prasa
A9: 1999 | B9: 15000 | C9: Beliner Zeitung | D9: prasa
A10: 2000 | B10: 5000 | C10: Gluckspilz | D10: policja
A11: 2000 | B11: 20000 | C11: Gluckspilz | D11: organizatorzy
A12: 2000 | B12: 15000 | C12: Gluckspilz | D12: prasa
A13: 2001 | B13: 6000 | C13: stressfaktor | D13: prasa
... A18: 2004 | B18: 3500 | C18: Umbruch | D18: prasa
A19: 2005 | B19: 0
A20: 2006 | B20: 0
A21: 2007 | B21: 3000 | C21: police | D21: policja
A22: 2007 | B22: 5000 | C22: Berliner Kurier | D22: prasa
A23: 2007 | B23: 15000 | C23: organisers via BZ | D23: organizatorzy
A24: 2008 | B24: 10000 | C24: police via taz | D24: policja
A25: 2008 | B25: 12000 | C25: "mehr als 10.000" ~ 12000 (Umbruch) | D25: organizatorzy
A26: 2009 | B26: 5000 | C26: police, via Tagesspiegel ticker 2010 | D26: policja
A27: 2009 | B27: 12000 | C27: "über 10.000 TeilnehmerInnen" ~ 12000 (Umbruch archiv) | D27: organizatorzy
A28: 2010 | B28: 10000 | C28: police, via Tagesspiegel ticker | D28: policja
A29: 2010 | B29: 15000 | C29: Umbruch Archiv | D29: organizatorzy
A30: 2011 | B30: 10000 | C30: taz | D30: prasa
A31: 2011 | B31: 9000 | C31: polica via BZ | D31: policja
A32: 2011 | B32: 15000 | C32: Umbruch | D32: organizatorzy
... A65: 2026 | B65: 11000 | C65: police | D65: policja

Sheet Średnie i wykres Revo
A1: Rok | B1: Prasa | C1: Organizatorzy | D1: Policja | E1: Średnia ogólna | F1: średnia metoda alt | G1: Różnica % | H1: średnia ruchoma
A2: 1996 | B2: =IFERROR(AVERAGEIFS(Dane_Revo!$B$2:$B$65,Dane_Revo!$A$2:$A$65,$A2,Dane_Revo!$D$2:$D$65,"prasa"),"") -> 10000 | C2: =IFERROR(AVERAGEIFS(Dane_Revo!$B$2:$B$65,Dane_Revo!$A$2:$A$65,$A2,Dane_Revo!$D$2:$D$65,"organizatorzy"),"") | D2: =IFERROR(AVERAGEIFS(Dane_Revo!$B$2:$B$65,Dane_Revo!$A$2:$A$65,$A2,Dane_Revo!$D$2:$D$65,"policja"),"") | E2: =IFERROR((0.5*IF(B2<>"",B2,0) + 0.25*IF(C2<>"",C2,0) + 0.25*IF(D2<>"",D2,0))/(0.5*IF(B2<>"",1,0) + 0.25*IF(C2<>"",1,0) + 0.25*IF(D2<>"",1,0)),"") -> 10000 | F2: =IFERROR(AVERAGEIFS(Dane_Revo!$B$2:$B$65,Dane_Revo!$A$2:$A$65,$A2),"") -> 10000 | G2: =E2-F2 -> 0
A3: 1997 | B3: =IFERROR(AVERAGEIFS(Dane_Revo!$B$2:$B$65,Dane_Revo!$A$2:$A$65,$A3,Dane_Revo!$D$2:$D$65,"prasa"),"") -> 9000 | C3: =IFERROR(AVERAGEIFS(Dane_Revo!$B$2:$B$65,Dane_Revo!$A$2:$A$65,$A3,Dane_Revo!$D$2:$D$65,"organizatorzy"),"") | D3: =IFERROR(AVERAGEIFS(Dane_Revo!$B$2:$B$65,Dane_Revo!$A$2:$A$65,$A3,Dane_Revo!$D$2:$D$65,"policja"),"") | E3: =IFERROR((0.5*IF(B3<>"",B3,0) + 0.25*IF(C3<>"",C3,0) + 0.25*IF(D3<>"",D3,0))/(0.5*IF(B3<>"",1,0) + 0.25*IF(C3<>"",1,0) + 0.25*IF(D3<>"",1,0)),"") -> 9000 | F3: =IFERROR(AVERAGEIFS(Dane_Revo!$B$2:$B$65,Dane_Revo!$A$2:$A$65,$A3),"") -> 9000 | G3: =E3-F3 -> 0 | H3: =AVERAGE(F2:F4) -> 8555.5556
A4: 1998 | B4: =IFERROR(AVERAGEIFS(Dane_Revo!$B$2:$B$65,Dane_Revo!$A$2:$A$65,$A4,Dane_Revo!$D$2:$D$65,"prasa"),"") -> 3000 | C4: =IFERROR(AVERAGEIFS(Dane_Revo!$B$2:$B$65,Dane_Revo!$A$2:$A$65,$A4,Dane_Revo!$D$2:$D$65,"organizatorzy"),"") -> 11000 | D4: =IFERROR(AVERAGEIFS(Dane_Revo!$B$2:$B$65,Dane_Revo!$A$2:$A$65,$A4,Dane_Revo!$D$2:$D$65,"policja"),"") -> 6000 | E4: =IFERROR((0.5*IF(B4<>"",B4,0) + 0.25*IF(C4<>"",C4,0) + 0.25*IF(D4<>"",D4,0))/(0.5*IF(B4<>"",1,0) + 0.25*IF(C4<>"",1,0) + 0.25*IF(D4<>"",1,0)),"") -> 5750 | F4: =IFERROR(AVERAGEIFS(Dane_Revo!$B$2:$B$65,Dane_Revo!$A$2:$A$65,$A4),"") -> 6666.6667 | G4: =E4-F4 -> -916.66667 | H4: =AVERAGE(F3:F5) -> 9888.8889
A5: 1999 | B5: =IFERROR(AVERAGEIFS(Dane_Revo!$B$2:$B$65,Dane_Revo!$A$2:$A$65,$A5,Dane_Revo!$D$2:$D$65,"prasa"),"") -> 14000 | C5: =IFERROR(AVERAGEIFS(Dane_Revo!$B$2:$B$65,Dane_Revo!$A$2:$A$65,$A5,Dane_Revo!$D$2:$D$65,"organizatorzy"),"") | D5: =IFERROR(AVERAGEIFS(Dane_Revo!$B$2:$B$65,Dane_Revo!$A$2:$A$65,$A5,Dane_Revo!$D$2:$D$65,"policja"),"") | E5: =IFERROR((0.5*IF(B5<>"",B5,0) + 0.25*IF(C5<>"",C5,0) + 0.25*IF(D5<>"",D5,0))/(0.5*IF(B5<>"",1,0) + 0.25*IF(C5<>"",1,0) + 0.25*IF(D5<>"",1,0)),"") -> 14000 | F5: =IFERROR(AVERAGEIFS(Dane_Revo!$B$2:$B$65,Dane_Revo!$A$2:$A$65,$A5),"") -> 14000 | G5: =E5-F5 -> 0 | H5: =AVERAGE(F4:F6) -> 11333.333
A6: 2000 | B6: =IFERROR(AVERAGEIFS(Dane_Revo!$B$2:$B$65,Dane_Revo!$A$2:$A$65,$A6,Dane_Revo!$D$2:$D$65,"prasa"),"") -> 15000 | C6: =IFERROR(AVERAGEIFS(Dane_Revo!$B$2:$B$65,Dane_Revo!$A$2:$A$65,$A6,Dane_Revo!$D$2:$D$65,"organizatorzy"),"") -> 20000 | D6: =IFERROR(AVERAGEIFS(Dane_Revo!$B$2:$B$65,Dane_Revo!$A$2:$A$65,$A6,Dane_Revo!$D$2:$D$65,"policja"),"") -> 5000 | E6: =IFERROR((0.5*IF(B6<>"",B6,0) + 0.25*IF(C6<>"",C6,0) + 0.25*IF(D6<>"",D6,0))/(0.5*IF(B6<>"",1,0) + 0.25*IF(C6<>"",1,0) + 0.25*IF(D6<>"",1,0)),"") -> 13750 | F6: =IFERROR(AVERAGEIFS(Dane_Revo!$B$2:$B$65,Dane_Revo!$A$2:$A$65,$A6),"") -> 13333.333 | G6: =E6-F6 -> 416.66667 | H6: =AVERAGE(F5:F7) -> 10944.444
A7: 2001 | B7: =IFERROR(AVERAGEIFS(Dane_Revo!$B$2:$B$65,Dane_Revo!$A$2:$A$65,$A7,Dane_Revo!$D$2:$D$65,"prasa"),"") -> 5500 | C7: =IFERROR(AVERAGEIFS(Dane_Revo!$B$2:$B$65,Dane_Revo!$A$2:$A$65,$A7,Dane_Revo!$D$2:$D$65,"organizatorzy"),"") | D7: =IFERROR(AVERAGEIFS(Dane_Revo!$B$2:$B$65,Dane_Revo!$A$2:$A$65,$A7,Dane_Revo!$D$2:$D$65,"policja"),"") | E7: =IFERROR((0.5*IF(B7<>"",B7,0) + 0.25*IF(C7<>"",C7,0) + 0.25*IF(D7<>"",D7,0))/(0.5*IF(B7<>"",1,0) + 0.25*IF(C7<>"",1,0) + 0.25*IF(D7<>"",1,0)),"") -> 5500 | F7: =IFERROR(AVERAGEIFS(Dane_Revo!$B$2:$B$65,Dane_Revo!$A$2:$A$65,$A7),"") -> 5500 | G7: =E7-F7 -> 0 | H7: =AVERAGE(F6:F8) -> 9444.4444
A8: 2002 | B8: =IFERROR(AVERAGEIFS(Dane_Revo!$B$2:$B$65,Dane_Revo!$A$2:$A$65,$A8,Dane_Revo!$D$2:$D$65,"prasa"),"") -> 9500 | C8: =IFERROR(AVERAGEIFS(Dane_Revo!$B$2:$B$65,Dane_Revo!$A$2:$A$65,$A8,Dane_Revo!$D$2:$D$65,"organizatorzy"),"") | D8: =IFERROR(AVERAGEIFS(Dane_Revo!$B$2:$B$65,Dane_Revo!$A$2:$A$65,$A8,Dane_Revo!$D$2:$D$65,"policja"),"") | E8: =IFERROR((0.5*IF(B8<>"",B8,0) + 0.25*IF(C8<>"",C8,0) + 0.25*IF(D8<>"",D8,0))/(0.5*IF(B8<>"",1,0) + 0.25*IF(C8<>"",1,0) + 0.25*IF(D8<>"",1,0)),"") -> 9500 | F8: =IFERROR(AVERAGEIFS(Dane_Revo!$B$2:$B$65,Dane_Revo!$A$2:$A$65,$A8),"") -> 9500 | G8: =E8-F8 -> 0 | H8: =AVERAGE(F7:F9) -> 6166.6667
A9: 2003 | B9: =IFERROR(AVERAGEIFS(Dane_Revo!$B$2:$B$65,Dane_Revo!$A$2:$A$65,$A9,Dane_Revo!$D$2:$D$65,"prasa"),"") -> 3500 | C9: =IFERROR(AVERAGEIFS(Dane_Revo!$B$2:$B$65,Dane_Revo!$A$2:$A$65,$A9,Dane_Revo!$D$2:$D$65,"organizatorzy"),"") | D9: =IFERROR(AVERAGEIFS(Dane_Revo!$B$2:$B$65,Dane_Revo!$A$2:$A$65,$A9,Dane_Revo!$D$2:$D$65,"policja"),"") | E9: =IFERROR((0.5*IF(B9<>"",B9,0) + 0.25*IF(C9<>"",C9,0) + 0.25*IF(D9<>"",D9,0))/(0.5*IF(B9<>"",1,0) + 0.25*IF(C9<>"",1,0) + 0.25*IF(D9<>"",1,0)),"") -> 3500 | F9: =IFERROR(AVERAGEIFS(Dane_Revo!$B$2:$B$65,Dane_Revo!$A$2:$A$65,$A9),"") -> 3500 | G9: =E9-F9 -> 0 | H9: =AVERAGE(F8:F10) -> 5500
A10: 2004 | B10: =IFERROR(AVERAGEIFS(Dane_Revo!$B$2:$B$65,Dane_Revo!$A$2:$A$65,$A10,Dane_Revo!$D$2:$D$65,"prasa"),"") -> 3500 | C10: =IFERROR(AVERAGEIFS(Dane_Revo!$B$2:$B$65,Dane_Revo!$A$2:$A$65,$A10,Dane_Revo!$D$2:$D$65,"organizatorzy"),"") | D10: =IFERROR(AVERAGEIFS(Dane_Revo!$B$2:$B$65,Dane_Revo!$A$2:$A$65,$A10,Dane_Revo!$D$2:$D$65,"policja"),"") | E10: =IFERROR((0.5*IF(B10<>"",B10,0) + 0.25*IF(C10<>"",C10,0) + 0.25*IF(D10<>"",D10,0))/(0.5*IF(B10<>"",1,0) + 0.25*IF(C10<>"",1,0) + 0.25*IF(D10<>"",1,0)),"") -> 3500 | F10: =IFERROR(AVERAGEIFS(Dane_Revo!$B$2:$B$65,Dane_Revo!$A$2:$A$65,$A10),"") -> 3500 | G10: =E10-F10 -> 0 | H10: =AVERAGE(F9:F11) -> 2333.3333
A11: 2005 | B11: =IFERROR(AVERAGEIFS(Dane_Revo!$B$2:$B$65,Dane_Revo!$A$2:$A$65,$A11,Dane_Revo!$D$2:$D$65,"prasa"),"") | C11: =IFERROR(AVERAGEIFS(Dane_Revo!$B$2:$B$65,Dane_Revo!$A$2:$A$65,$A11,Dane_Revo!$D$2:$D$65,"organizatorzy"),"") | D11: =IFERROR(AVERAGEIFS(Dane_Revo!$B$2:$B$65,Dane_Revo!$A$2:$A$65,$A11,Dane_Revo!$D$2:$D$65,"policja"),"") | E11: =IFERROR((0.5*IF(B11<>"",B11,0) + 0.25*IF(C11<>"",C11,0) + 0.25*IF(D11<>"",D11,0))/(0.5*IF(B11<>"",1,0) + 0.25*IF(C11<>"",1,0) + 0.25*IF(D11<>"",1,0)),"") | F11: =IFERROR(AVERAGEIFS(Dane_Revo!$B$2:$B$65,Dane_Revo!$A$2:$A$65,$A11),"") -> 0 | G11: =E11-F11 -> 0 | H11: =AVERAGE(F10:F12) -> 1166.6667
A12: 2006 | B12: =IFERROR(AVERAGEIFS(Dane_Revo!$B$2:$B$65,Dane_Revo!$A$2:$A$65,$A12,Dane_Revo!$D$2:$D$65,"prasa"),"") | C12: =IFERROR(AVERAGEIFS(Dane_Revo!$B$2:$B$65,Dane_Revo!$A$2:$A$65,$A12,Dane_Revo!$D$2:$D$65,"organizatorzy"),"") | D12: =IFERROR(AVERAGEIFS(Dane_Revo!$B$2:$B$65,Dane_Revo!$A$2:$A$65,$A12,Dane_Revo!$D$2:$D$65,"policja"),"") | E12: =IFERROR((0.5*IF(B12<>"",B12,0) + 0.25*IF(C12<>"",C12,0) + 0.25*IF(D12<>"",D12,0))/(0.5*IF(B12<>"",1,0) + 0.25*IF(C12<>"",1,0) + 0.25*IF(D12<>"",1,0)),"") | F12: =IFERROR(AVERAGEIFS(Dane_Revo!$B$2:$B$65,Dane_Revo!$A$2:$A$65,$A12),"") -> 0 | G12: =E12-F12 -> 0 | H12: =AVERAGE(F11:F13) -> 2555.5556
A13: 2007 | B13: =IFERROR(AVERAGEIFS(Dane_Revo!$B$2:$B$65,Dane_Revo!$A$2:$A$65,$A13,Dane_Revo!$D$2:$D$65,"prasa"),"") -> 5000 | C13: =IFERROR(AVERAGEIFS(Dane_Revo!$B$2:$B$65,Dane_Revo!$A$2:$A$65,$A13,Dane_Revo!$D$2:$D$65,"organizatorzy"),"") -> 15000 | D13: =IFERROR(AVERAGEIFS(Dane_Revo!$B$2:$B$65,Dane_Revo!$A$2:$A$65,$A13,Dane_Revo!$D$2:$D$65,"policja"),"") -> 3000 | E13: =IFERROR((0.5*IF(B13<>"",B13,0) + 0.25*IF(C13<>"",C13,0) + 0.25*IF(D13<>"",D13,0))/(0.5*IF(B13<>"",1,0) + 0.25*IF(C13<>"",1,0) + 0.25*IF(D13<>"",1,0)),"") -> 7000 | F13: =IFERROR(AVERAGEIFS(Dane_Revo!$B$2:$B$65,Dane_Revo!$A$2:$A$65,$A13),"") -> 7666.6667 | G13: =E13-F13 -> -666.66667 | H13: =AVERAGE(F12:F14) -> 6222.2222
A14: 2008 | B14: =IFERROR(AVERAGEIFS(Dane_Revo!$B$2:$B$65,Dane_Revo!$A$2:$A$65,$A14,Dane_Revo!$D$2:$D$65,"prasa"),"") | C14: =IFERROR(AVERAGEIFS(Dane_Revo!$B$2:$B$65,Dane_Revo!$A$2:$A$65,$A14,Dane_Revo!$D$2:$D$65,"organizatorzy"),"") -> 12000 | D14: =IFERROR(AVERAGEIFS(Dane_Revo!$B$2:$B$65,Dane_Revo!$A$2:$A$65,$A14,Dane_Revo!$D$2:$D$65,"policja"),"") -> 10000 | E14: =IFERROR((0.5*IF(B14<>"",B14,0) + 0.25*IF(C14<>"",C14,0) + 0.25*IF(D14<>"",D14,0))/(0.5*IF(B14<>"",1,0) + 0.25*IF(C14<>"",1,0) + 0.25*IF(D14<>"",1,0)),"") -> 11000 | F14: =IFERROR(AVERAGEIFS(Dane_Revo!$B$2:$B$65,Dane_Revo!$A$2:$A$65,$A14),"") -> 11000 | G14: =E14-F14 -> 0 | H14: =AVERAGE(F13:F15) -> 9055.5556
... A31: 2025 | B31: =IFERROR(AVERAGEIFS(Dane_Revo!$B$2:$B$65,Dane_Revo!$A$2:$A$65,$A31,Dane_Revo!$D$2:$D$65,"prasa"),"") | C31: =IFERROR(AVERAGEIFS(Dane_Revo!$B$2:$B$65,Dane_Revo!$A$2:$A$65,$A31,Dane_Revo!$D$2:$D$65,"organizatorzy"),"") -> 30000 | D31: =IFERROR(AVERAGEIFS(Dane_Revo!$B$2:$B$65,Dane_Revo!$A$2:$A$65,$A31,Dane_Revo!$D$2:$D$65,"policja"),"") -> 22000 | E31: =IFERROR((0.5*IF(B31<>"",B31,0) + 0.25*IF(C31<>"",C31,0) + 0.25*IF(D31<>"",D31,0))/(0.5*IF(B31<>"",1,0) + 0.25*IF(C31<>"",1,0) + 0.25*IF(D31<>"",1,0)),"") -> 26000 | F31: =IFERROR(AVERAGEIFS(Dane_Revo!$B$2:$B$65,Dane_Revo!$A$2:$A$65,$A31),"") -> 26000 | G31: =E31-F31 -> 0 | H31: =AVERAGE(F30:F32) -> 21255.556
A32: 2026 | B32: =IFERROR(AVERAGEIFS(Dane_Revo!$B$2:$B$65,Dane_Revo!$A$2:$A$65,$A32,Dane_Revo!$D$2:$D$65,"prasa"),"") | C32: =IFERROR(AVERAGEIFS(Dane_Revo!$B$2:$B$65,Dane_Revo!$A$2:$A$65,$A32,Dane_Revo!$D$2:$D$65,"organizatorzy"),"") -> 30000 | D32: =IFERROR(AVERAGEIFS(Dane_Revo!$B$2:$B$65,Dane_Revo!$A$2:$A$65,$A32,Dane_Revo!$D$2:$D$65,"policja"),"") -> 11000 | E32: =IFERROR((0.5*IF(B32<>"",B32,0) + 0.25*IF(C32<>"",C32,0) + 0.25*IF(D32<>"",D32,0))/(0.5*IF(B32<>"",1,0) + 0.25*IF(C32<>"",1,0) + 0.25*IF(D32<>"",1,0)),"") -> 20500 | F32: =IFERROR(AVERAGEIFS(Dane_Revo!$B$2:$B$65,Dane_Revo!$A$2:$A$65,$A32),"") -> 20500 | G32: =E32-F32 -> 0
D34: =IFERROR(__xludf.DUMMYFUNCTION("join("", "",F2:F32)"),"10000, 9000, 6667, 14000, 13333, 5500, 9500, 3500, 3500, 0, 0, 7667, 11000, 8500, 12500, 11333, 18500, 11667, 22000, 25500, 16500, 15000, 12500, 10000, 3000, 14500, 17000, 16000, 17267, 26000, 20500") -> 10000, 9000, 6667, 14000, 13333, 5500, 9500, 3500, 3500, 0, 0, 7667, 11000, 8500, 12500, 11333, 18500, 11667, 22000, 25500, 16500, 15000, 12500, 10000, 3000, 14500, 17000, 16000, 17267, 26000, 20500

Sheet Dane_Antinazi
A1: Rok | B1: Liczba uczestników | C1: Źródło | D1: Kategoria | E1: Dane Antinazi
A2: 1992 | B2: 200 | C2: Gluckspilz | D2: prasa
A3: 1993
A4: 1994 | B4: 400 | C4: taz | D4: prasa
A5: 1994 | B5: 500 | C5: Gluckspilz | D5: prasa
A6: 1996 | B6: 40 | C6: Breitenbach (JW 3.05) | D6: organizatorzy
A7: 2000 | B7: 10000 | C7: ND | D7: prasa
A8: 2001 | B8: 350 | C8: taz | D8: prasa
A9: 2001 | B9: 600 | C9: Tsg, s. 11 | D9: prasa
A10: 2002 | B10: 1000 | C10: taz | D10: prasa
A11: 2003 | B11: 200 | C11: LÖPA | D11: prasa
A12: 2003 | B12: 300 | C12: taz | D12: prasa
A13: 2004 | B13: 2300 | C13: LÖPA | D13: prasa
A14: 2004 | B14: 4500 | C14: Umbruch | D14: prasa
A15: 2009 | B15: 3500 | C15: Polizeiliche darstellung | D15: policja
... A20: 2017 | B20: 600 | C20: Berliner Bundnis gegen Rechts | D20: organizatorzy
A21: 2018
A22: 2019 | B22: 500 | C22: nd | D22: prasa

Sheet Średnie i wykres Antinazi
A1: Rok | B1: Prasa | C1: Organizatorzy | D1: Policja | E1: Średnia ogólna | F1: średnia metoda alt | G1: Różnica %
A2: 1990 | B2: =IFERROR(AVERAGEIFS(Dane_Antinazi!$B$2:$B$22,Dane_Antinazi!$A$2:$A$22,$A2,Dane_Antinazi!$D$2:$D$22,"prasa"),"") | C2: =IFERROR(AVERAGEIFS(Dane_Antinazi!$B$2:$B$22,Dane_Antinazi!$A$2:$A$22,$A2,Dane_Antinazi!$D$2:$D$22,"organizatorzy"),"") | D2: =IFERROR(AVERAGEIFS(Dane_Antinazi!$B$2:$B$22,Dane_Antinazi!$A$2:$A$22,$A2,Dane_Antinazi!$D$2:$D$22,"policja"),"") | E2: =IFERROR((0.5*IF(B2<>"",B2,0) + 0.25*IF(C2<>"",C2,0) + 0.25*IF(D2<>"",D2,0))/(0.5*IF(B2<>"",1,0) + 0.25*IF(C2<>"",1,0) + 0.25*IF(D2<>"",1,0)),"") | F2: =IFERROR(AVERAGEIFS(Dane_Antinazi!$B$2:$B$22,Dane_Antinazi!$A$2:$A$22,$A2),"") | G2: =E2-F2 -> 0
A3: 1991 | B3: =IFERROR(AVERAGEIFS(Dane_Antinazi!$B$2:$B$22,Dane_Antinazi!$A$2:$A$22,$A3,Dane_Antinazi!$D$2:$D$22,"prasa"),"") | C3: =IFERROR(AVERAGEIFS(Dane_Antinazi!$B$2:$B$22,Dane_Antinazi!$A$2:$A$22,$A3,Dane_Antinazi!$D$2:$D$22,"organizatorzy"),"") | D3: =IFERROR(AVERAGEIFS(Dane_Antinazi!$B$2:$B$22,Dane_Antinazi!$A$2:$A$22,$A3,Dane_Antinazi!$D$2:$D$22,"policja"),"") | E3: =IFERROR((0.5*IF(B3<>"",B3,0) + 0.25*IF(C3<>"",C3,0) + 0.25*IF(D3<>"",D3,0))/(0.5*IF(B3<>"",1,0) + 0.25*IF(C3<>"",1,0) + 0.25*IF(D3<>"",1,0)),"") | F3: =IFERROR(AVERAGEIFS(Dane_Antinazi!$B$2:$B$22,Dane_Antinazi!$A$2:$A$22,$A3),"") | G3: =E3-F3 -> 0
A4: 1992 | B4: =IFERROR(AVERAGEIFS(Dane_Antinazi!$B$2:$B$22,Dane_Antinazi!$A$2:$A$22,$A4,Dane_Antinazi!$D$2:$D$22,"prasa"),"") -> 200 | C4: =IFERROR(AVERAGEIFS(Dane_Antinazi!$B$2:$B$22,Dane_Antinazi!$A$2:$A$22,$A4,Dane_Antinazi!$D$2:$D$22,"organizatorzy"),"") | D4: =IFERROR(AVERAGEIFS(Dane_Antinazi!$B$2:$B$22,Dane_Antinazi!$A$2:$A$22,$A4,Dane_Antinazi!$D$2:$D$22,"policja"),"") | E4: =IFERROR((0.5*IF(B4<>"",B4,0) + 0.25*IF(C4<>"",C4,0) + 0.25*IF(D4<>"",D4,0))/(0.5*IF(B4<>"",1,0) + 0.25*IF(C4<>"",1,0) + 0.25*IF(D4<>"",1,0)),"") -> 200 | F4: =IFERROR(AVERAGEIFS(Dane_Antinazi!$B$2:$B$22,Dane_Antinazi!$A$2:$A$22,$A4),"") -> 200 | G4: =E4-F4 -> 0
A5: 1993 | B5: =IFERROR(AVERAGEIFS(Dane_Antinazi!$B$2:$B$22,Dane_Antinazi!$A$2:$A$22,$A5,Dane_Antinazi!$D$2:$D$22,"prasa"),"") | C5: =IFERROR(AVERAGEIFS(Dane_Antinazi!$B$2:$B$22,Dane_Antinazi!$A$2:$A$22,$A5,Dane_Antinazi!$D$2:$D$22,"organizatorzy"),"") | D5: =IFERROR(AVERAGEIFS(Dane_Antinazi!$B$2:$B$22,Dane_Antinazi!$A$2:$A$22,$A5,Dane_Antinazi!$D$2:$D$22,"policja"),"") | E5: =IFERROR((0.5*IF(B5<>"",B5,0) + 0.25*IF(C5<>"",C5,0) + 0.25*IF(D5<>"",D5,0))/(0.5*IF(B5<>"",1,0) + 0.25*IF(C5<>"",1,0) + 0.25*IF(D5<>"",1,0)),"") | F5: =IFERROR(AVERAGEIFS(Dane_Antinazi!$B$2:$B$22,Dane_Antinazi!$A$2:$A$22,$A5),"") | G5: =E5-F5 -> 0
A6: 1994 | B6: =IFERROR(AVERAGEIFS(Dane_Antinazi!$B$2:$B$22,Dane_Antinazi!$A$2:$A$22,$A6,Dane_Antinazi!$D$2:$D$22,"prasa"),"") -> 450 | C6: =IFERROR(AVERAGEIFS(Dane_Antinazi!$B$2:$B$22,Dane_Antinazi!$A$2:$A$22,$A6,Dane_Antinazi!$D$2:$D$22,"organizatorzy"),"") | D6: =IFERROR(AVERAGEIFS(Dane_Antinazi!$B$2:$B$22,Dane_Antinazi!$A$2:$A$22,$A6,Dane_Antinazi!$D$2:$D$22,"policja"),"") | E6: =IFERROR((0.5*IF(B6<>"",B6,0) + 0.25*IF(C6<>"",C6,0) + 0.25*IF(D6<>"",D6,0))/(0.5*IF(B6<>"",1,0) + 0.25*IF(C6<>"",1,0) + 0.25*IF(D6<>"",1,0)),"") -> 450 | F6: =IFERROR(AVERAGEIFS(Dane_Antinazi!$B$2:$B$22,Dane_Antinazi!$A$2:$A$22,$A6),"") -> 450 | G6: =E6-F6 -> 0
A7: 1995 | B7: =IFERROR(AVERAGEIFS(Dane_Antinazi!$B$2:$B$22,Dane_Antinazi!$A$2:$A$22,$A7,Dane_Antinazi!$D$2:$D$22,"prasa"),"") | C7: =IFERROR(AVERAGEIFS(Dane_Antinazi!$B$2:$B$22,Dane_Antinazi!$A$2:$A$22,$A7,Dane_Antinazi!$D$2:$D$22,"organizatorzy"),"") | D7: =IFERROR(AVERAGEIFS(Dane_Antinazi!$B$2:$B$22,Dane_Antinazi!$A$2:$A$22,$A7,Dane_Antinazi!$D$2:$D$22,"policja"),"") | E7: =IFERROR((0.5*IF(B7<>"",B7,0) + 0.25*IF(C7<>"",C7,0) + 0.25*IF(D7<>"",D7,0))/(0.5*IF(B7<>"",1,0) + 0.25*IF(C7<>"",1,0) + 0.25*IF(D7<>"",1,0)),"") | F7: =IFERROR(AVERAGEIFS(Dane_Antinazi!$B$2:$B$22,Dane_Antinazi!$A$2:$A$22,$A7),"") | G7: =E7-F7 -> 0
A8: 1996 | B8: =IFERROR(AVERAGEIFS(Dane_Antinazi!$B$2:$B$22,Dane_Antinazi!$A$2:$A$22,$A8,Dane_Antinazi!$D$2:$D$22,"prasa"),"") | C8: =IFERROR(AVERAGEIFS(Dane_Antinazi!$B$2:$B$22,Dane_Antinazi!$A$2:$A$22,$A8,Dane_Antinazi!$D$2:$D$22,"organizatorzy"),"") -> 40 | D8: =IFERROR(AVERAGEIFS(Dane_Antinazi!$B$2:$B$22,Dane_Antinazi!$A$2:$A$22,$A8,Dane_Antinazi!$D$2:$D$22,"policja"),"") | E8: =IFERROR((0.5*IF(B8<>"",B8,0) + 0.25*IF(C8<>"",C8,0) + 0.25*IF(D8<>"",D8,0))/(0.5*IF(B8<>"",1,0) + 0.25*IF(C8<>"",1,0) + 0.25*IF(D8<>"",1,0)),"") -> 40 | F8: =IFERROR(AVERAGEIFS(Dane_Antinazi!$B$2:$B$22,Dane_Antinazi!$A$2:$A$22,$A8),"") -> 40 | G8: =E8-F8 -> 0
A9: 1997 | B9: =IFERROR(AVERAGEIFS(Dane_Antinazi!$B$2:$B$22,Dane_Antinazi!$A$2:$A$22,$A9,Dane_Antinazi!$D$2:$D$22,"prasa"),"") | C9: =IFERROR(AVERAGEIFS(Dane_Antinazi!$B$2:$B$22,Dane_Antinazi!$A$2:$A$22,$A9,Dane_Antinazi!$D$2:$D$22,"organizatorzy"),"") | D9: =IFERROR(AVERAGEIFS(Dane_Antinazi!$B$2:$B$22,Dane_Antinazi!$A$2:$A$22,$A9,Dane_Antinazi!$D$2:$D$22,"policja"),"") | E9: =IFERROR((0.5*IF(B9<>"",B9,0) + 0.25*IF(C9<>"",C9,0) + 0.25*IF(D9<>"",D9,0))/(0.5*IF(B9<>"",1,0) + 0.25*IF(C9<>"",1,0) + 0.25*IF(D9<>"",1,0)),"") | F9: =IFERROR(AVERAGEIFS(Dane_Antinazi!$B$2:$B$22,Dane_Antinazi!$A$2:$A$22,$A9),"") | G9: =E9-F9 -> 0
A10: 1998 | B10: =IFERROR(AVERAGEIFS(Dane_Antinazi!$B$2:$B$22,Dane_Antinazi!$A$2:$A$22,$A10,Dane_Antinazi!$D$2:$D$22,"prasa"),"") | C10: =IFERROR(AVERAGEIFS(Dane_Antinazi!$B$2:$B$22,Dane_Antinazi!$A$2:$A$22,$A10,Dane_Antinazi!$D$2:$D$22,"organizatorzy"),"") | D10: =IFERROR(AVERAGEIFS(Dane_Antinazi!$B$2:$B$22,Dane_Antinazi!$A$2:$A$22,$A10,Dane_Antinazi!$D$2:$D$22,"policja"),"") | E10: =IFERROR((0.5*IF(B10<>"",B10,0) + 0.25*IF(C10<>"",C10,0) + 0.25*IF(D10<>"",D10,0))/(0.5*IF(B10<>"",1,0) + 0.25*IF(C10<>"",1,0) + 0.25*IF(D10<>"",1,0)),"") | F10: =IFERROR(AVERAGEIFS(Dane_Antinazi!$B$2:$B$22,Dane_Antinazi!$A$2:$A$22,$A10),"") | G10: =E10-F10 -> 0
A11: 1999 | B11: =IFERROR(AVERAGEIFS(Dane_Antinazi!$B$2:$B$22,Dane_Antinazi!$A$2:$A$22,$A11,Dane_Antinazi!$D$2:$D$22,"prasa"),"") | C11: =IFERROR(AVERAGEIFS(Dane_Antinazi!$B$2:$B$22,Dane_Antinazi!$A$2:$A$22,$A11,Dane_Antinazi!$D$2:$D$22,"organizatorzy"),"") | D11: =IFERROR(AVERAGEIFS(Dane_Antinazi!$B$2:$B$22,Dane_Antinazi!$A$2:$A$22,$A11,Dane_Antinazi!$D$2:$D$22,"policja"),"") | E11: =IFERROR((0.5*IF(B11<>"",B11,0) + 0.25*IF(C11<>"",C11,0) + 0.25*IF(D11<>"",D11,0))/(0.5*IF(B11<>"",1,0) + 0.25*IF(C11<>"",1,0) + 0.25*IF(D11<>"",1,0)),"") | F11: =IFERROR(AVERAGEIFS(Dane_Antinazi!$B$2:$B$22,Dane_Antinazi!$A$2:$A$22,$A11),"") | G11: =E11-F11 -> 0
A12: 2000 | B12: =IFERROR(AVERAGEIFS(Dane_Antinazi!$B$2:$B$22,Dane_Antinazi!$A$2:$A$22,$A12,Dane_Antinazi!$D$2:$D$22,"prasa"),"") -> 10000 | C12: =IFERROR(AVERAGEIFS(Dane_Antinazi!$B$2:$B$22,Dane_Antinazi!$A$2:$A$22,$A12,Dane_Antinazi!$D$2:$D$22,"organizatorzy"),"") | D12: =IFERROR(AVERAGEIFS(Dane_Antinazi!$B$2:$B$22,Dane_Antinazi!$A$2:$A$22,$A12,Dane_Antinazi!$D$2:$D$22,"policja"),"") | E12: =IFERROR((0.5*IF(B12<>"",B12,0) + 0.25*IF(C12<>"",C12,0) + 0.25*IF(D12<>"",D12,0))/(0.5*IF(B12<>"",1,0) + 0.25*IF(C12<>"",1,0) + 0.25*IF(D12<>"",1,0)),"") -> 10000 | F12: =IFERROR(AVERAGEIFS(Dane_Antinazi!$B$2:$B$22,Dane_Antinazi!$A$2:$A$22,$A12),"") -> 10000 | G12: =E12-F12 -> 0
A13: 2001 | B13: =IFERROR(AVERAGEIFS(Dane_Antinazi!$B$2:$B$22,Dane_Antinazi!$A$2:$A$22,$A13,Dane_Antinazi!$D$2:$D$22,"prasa"),"") -> 475 | C13: =IFERROR(AVERAGEIFS(Dane_Antinazi!$B$2:$B$22,Dane_Antinazi!$A$2:$A$22,$A13,Dane_Antinazi!$D$2:$D$22,"organizatorzy"),"") | D13: =IFERROR(AVERAGEIFS(Dane_Antinazi!$B$2:$B$22,Dane_Antinazi!$A$2:$A$22,$A13,Dane_Antinazi!$D$2:$D$22,"policja"),"") | E13: =IFERROR((0.5*IF(B13<>"",B13,0) + 0.25*IF(C13<>"",C13,0) + 0.25*IF(D13<>"",D13,0))/(0.5*IF(B13<>"",1,0) + 0.25*IF(C13<>"",1,0) + 0.25*IF(D13<>"",1,0)),"") -> 475 | F13: =IFERROR(AVERAGEIFS(Dane_Antinazi!$B$2:$B$22,Dane_Antinazi!$A$2:$A$22,$A13),"") -> 475 | G13: =E13-F13 -> 0
... A31: 2019 | B31: =IFERROR(AVERAGEIFS(Dane_Antinazi!$B$2:$B$22,Dane_Antinazi!$A$2:$A$22,$A31,Dane_Antinazi!$D$2:$D$22,"prasa"),"") -> 500 | C31: =IFERROR(AVERAGEIFS(Dane_Antinazi!$B$2:$B$22,Dane_Antinazi!$A$2:$A$22,$A31,Dane_Antinazi!$D$2:$D$22,"organizatorzy"),"") | D31: =IFERROR(AVERAGEIFS(Dane_Antinazi!$B$2:$B$22,Dane_Antinazi!$A$2:$A$22,$A31,Dane_Antinazi!$D$2:$D$22,"policja"),"") | E31: =IFERROR((0.5*IF(B31<>"",B31,0) + 0.25*IF(C31<>"",C31,0) + 0.25*IF(D31<>"",D31,0))/(0.5*IF(B31<>"",1,0) + 0.25*IF(C31<>"",1,0) + 0.25*IF(D31<>"",1,0)),"") -> 500 | F31: =IFERROR(AVERAGEIFS(Dane_Antinazi!$B$2:$B$22,Dane_Antinazi!$A$2:$A$22,$A31),"") -> 500 | G31: =E31-F31 -> 0
E32: =IFERROR( (0.5*IF(B32<>"",B32,0) + 0.25*IF(C32<>"",C32,0) + 0.25*IF(D32<>"",D32,0)) / (0.5*IF(B32<>"",1,0) + 0.25*IF(C32<>"",1,0) + 0.25*IF(D32<>"",1,0)) ,"")
D37: =IFERROR(__xludf.DUMMYFUNCTION("JOIN("", "", IF(F2:F32="""", ""null"", F2:F32))"),"#VALUE!") -> #VALUE!
